Workbook

Sheet NAsource
A1: Amazon (AMZN) stock prices May 1997 - November 2017.
A2: Downloaded from finance.yahoo.com.

Sheet Table
A1: Date | B1: Open | C1: High | D1: Low | E1: Close | F1: Volume | G1: Adj Close | H1: Daily Range | I1: Daily Range % | J1: Daily Change | K1: Daily Change % | L1: Adjustment ratio | M1: Adjusted High Price | N1: Adjusted Low price | O1: Adj. Close Change since first day | P1: Adj. Close change percentage since first day
A2: 43054 | B2: 1127.01 | C2: 1131.75 | D2: 1121.63 | E2: 1126.69 | F2: 3905400 | G2: 1126.69 | H2: =C2-D2 -> 10.12 | I2: =(C2-D2)/D2 -> 0.0090225832 | J2: =G2-G3 -> -10.15 | K2: =(G2-G3)/G3 -> -0.0089282573 | L2: =G2/E2 -> 1 | M2: =L2*C2 -> 1131.75 | N2: =L2*D2 -> 1121.63 | O2: =G2-$G$5163 -> 1124.73 | P2: =(G2-$G$5163)/$G$5163 -> 573.84184
A3: 43053 | B3: 1130.11 | C3: 1138 | D3: 1123.89 | E3: 1136.84 | F3: 3138400 | G3: 1136.84 | H3: =C3-D3 -> 14.11 | I3: =(C3-D3)/D3 -> 0.012554609 | J3: =G3-G4 -> 7.67 | K3: =(G3-G4)/G4 -> 0.0067925999 | L3: =G3/E3 -> 1 | M3: =L3*C3 -> 1138 | N3: =L3*D3 -> 1123.89 | O3: =G3-$G$5163 -> 1134.88 | P3: =(G3-$G$5163)/$G$5163 -> 579.02041
A4: 43052 | B4: 1123 | C4: 1139.9 | D4: 1122.34 | E4: 1129.17 | F4: 2918400 | G4: 1129.17 | H4: =C4-D4 -> 17.56 | I4: =(C4-D4)/D4 -> 0.015645883 | J4: =G4-G5 -> 3.82 | K4: =(G4-G5)/G5 -> 0.0033944995 | L4: =G4/E4 -> 1 | M4: =L4*C4 -> 1139.9 | N4: =L4*D4 -> 1122.34 | O4: =G4-$G$5163 -> 1127.21 | P4: =(G4-$G$5163)/$G$5163 -> 575.10714
A5: 43049 | B5: 1126.1 | C5: 1131.75 | D5: 1124.06 | E5: 1125.35 | F5: 2179900 | G5: 1125.35 | H5: =C5-D5 -> 7.69 | I5: =(C5-D5)/D5 -> 0.0068412718 | J5: =G5-G6 -> -3.78 | K5: =(G5-G6)/G6 -> -0.0033477102 | L5: =G5/E5 -> 1 | M5: =L5*C5 -> 1131.75 | N5: =L5*D5 -> 1124.06 | O5: =G5-$G$5163 -> 1123.39 | P5: =(G5-$G$5163)/$G$5163 -> 573.15816
A6: 43048 | B6: 1125.96 | C6: 1129.62 | D6: 1115.77 | E6: 1129.13 | F6: 3732700 | G6: 1129.13 | H6: =C6-D6 -> 13.85 | I6: =(C6-D6)/D6 -> 0.012412952 | J6: =G6-G7 -> -3.75 | K6: =(G6-G7)/G7 -> -0.0033101476 | L6: =G6/E6 -> 1 | M6: =L6*C6 -> 1129.62 | N6: =L6*D6 -> 1115.77 | O6: =G6-$G$5163 -> 1127.17 | P6: =(G6-$G$5163)/$G$5163 -> 575.08673
A7: 43047 | B7: 1122.82 | C7: 1135.54 | D7: 1119.11 | E7: 1132.88 | F7: 2581500 | G7: 1132.88 | H7: =C7-D7 -> 16.43 | I7: =(C7-D7)/D7 -> 0.014681309 | J7: =G7-G8 -> 9.71 | K7: =(G7-G8)/G8 -> 0.0086451739 | L7: =G7/E7 -> 1 | M7: =L7*C7 -> 1135.54 | N7: =L7*D7 -> 1119.11 | O7: =G7-$G$5163 -> 1130.92 | P7: =(G7-$G$5163)/$G$5163 -> 577
A8: 43046 | B8: 1124.74 | C8: 1130.6 | D8: 1117.5 | E8: 1123.17 | F8: 2689000 | G8: 1123.17 | H8: =C8-D8 -> 13.1 | I8: =(C8-D8)/D8 -> 0.011722595 | J8: =G8-G9 -> 2.51 | K8: =(G8-G9)/G9 -> 0.0022397516 | L8: =G8/E8 -> 1 | M8: =L8*C8 -> 1130.6 | N8: =L8*D8 -> 1117.5 | O8: =G8-$G$5163 -> 1121.21 | P8: =(G8-$G$5163)/$G$5163 -> 572.04592
A9: 43045 | B9: 1109.15 | C9: 1125.41 | D9: 1108.77 | E9: 1120.66 | F9: 3381100 | G9: 1120.66 | H9: =C9-D9 -> 16.64 | I9: =(C9-D9)/D9 -> 0.015007621 | J9: =G9-G10 -> 9.06 | K9: =(G9-G10)/G10 -> 0.0081504138 | L9: =G9/E9 -> 1 | M9: =L9*C9 -> 1125.41 | N9: =L9*D9 -> 1108.77 | O9: =G9-$G$5163 -> 1118.7 | P9: =(G9-$G$5163)/$G$5163 -> 570.76531
A10: 43042 | B10: 1091.15 | C10: 1112.68 | D10: 1088.52 | E10: 1111.6 | F10: 3751500 | G10: 1111.6 | H10: =C10-D10 -> 24.16 | I10: =(C10-D10)/D10 -> 0.022195274 | J10: =G10-G11 -> 17.38 | K10: =(G10-G11)/G11 -> 0.01588346 | L10: =G10/E10 -> 1 | M10: =L10*C10 -> 1112.68 | N10: =L10*D10 -> 1088.52 | O10: =G10-$G$5163 -> 1109.64 | P10: =(G10-$G$5163)/$G$5163 -> 566.14286
A11: 43041 | B11: 1097.81 | C11: 1101.94 | D11: 1086.87 | E11: 1094.22 | F11: 3684900 | G11: 1094.22 | H11: =C11-D11 -> 15.07 | I11: =(C11-D11)/D11 -> 0.013865504 | J11: =G11-G12 -> -9.46 | K11: =(G11-G12)/G12 -> -0.008571325 | L11: =G11/E11 -> 1 | M11: =L11*C11 -> 1101.94 | N11: =L11*D11 -> 1086.87 | O11: =G11-$G$5163 -> 1092.26 | P11: =(G11-$G$5163)/$G$5163 -> 557.27551
A12: 43040 | B12: 1105.4 | C12: 1108.97 | D12: 1096.74 | E12: 1103.68 | F12: 3755500 | G12: 1103.68 | H12: =C12-D12 -> 12.23 | I12: =(C12-D12)/D12 -> 0.01115123 | J12: =G12-G13 -> -1.6 | K12: =(G12-G13)/G13 -> -0.001447597 | L12: =G12/E12 -> 1 | M12: =L12*C12 -> 1108.97 | N12: =L12*D12 -> 1096.74 | O12: =G12-$G$5163 -> 1101.72 | P12: =(G12-$G$5163)/$G$5163 -> 562.10204
A13: 43039 | B13: 1109 | C13: 1110.54 | D13: 1101.12 | E13: 1105.28 | F13: 3477000 | G13: 1105.28 | H13: =C13-D13 -> 9.42 | I13: =(C13-D13)/D13 -> 0.0085549259 | J13: =G13-G14 -> -5.57 | K13: =(G13-G14)/G14 -> -0.0050141783 | L13: =G13/E13 -> 1 | M13: =L13*C13 -> 1110.54 | N13: =L13*D13 -> 1101.12 | O13: =G13-$G$5163 -> 1103.32 | P13: =(G13-$G$5163)/$G$5163 -> 562.91837
... A5162: 35566 | B5162: 23.63 | C5162: 23.75 | D5162: 20.51 | E5162: 20.75 | F5162: 14700000 | G5162: 1.73 | H5162: =C5162-D5162 -> 3.24 | I5162: =(C5162-D5162)/D5162 -> 0.15797172 | J5162: =G5162-G5163 -> -0.23 | K5162: =(G5162-G5163)/G5163 -> -0.11734694 | L5162: =G5162/E5162 -> 0.083373494 | M5162: =L5162*C5162 -> 1.9801205 | N5162: =L5162*D5162 -> 1.7099904 | O5162: =G5162-$G$5163 -> -0.23 | P5162: =(G5162-$G$5163)/$G$5163 -> -0.11734694
A5163: 35565 | B5163: 29.26 | C5163: 29.97 | D5163: 23.14 | E5163: 23.5 | F5163: 72156000 | G5163: 1.96 | H5163: =C5163-D5163 -> 6.83 | I5163: =(C5163-D5163)/D5163 -> 0.2951599 | L5163: =G5163/E5163 -> 0.083404255 | M5163: =L5163*C5163 -> 2.4996255 | N5163: =L5163*D5163 -> 1.9299745 | O5163: =G5163-$G$5163 -> 0 | P5163: =(G5163-$G$5163)/$G$5163 -> 0

Sheet Amazon Stock Price Analysis
A1: Part 1:
B2: Daily Range
A3: Date | B3: High | C3: Low | D3: Daily Range | E3: Daily Range % | F3: Adj.Close | G3: Adj Close previous day | H3: Daily Change | I3: Daily C
A4: 42117 | B4: =_xlfn.XLOOKUP(A4,Table!A:A, Table!C:C) -> 391.88 | C4: =_xlfn.XLOOKUP(A4,Table!A:A, Table!D:D) -> 386.15 | D4: =B4-C4 -> 5.73 | E4: =(B4-C4)/C4 -> 0.014838793 | F4: =_xlfn.XLOOKUP(A4,Table!A:A, Table!G:G) -> 389.99
A5: 42151 | B5: =_xlfn.XLOOKUP(A5,Table!A:A, Table!C:C) -> 431.85 | C5: =_xlfn.XLOOKUP(A5,Table!A:A, Table!D:D) -> 425.01 | D5: =B5-C5 -> 6.84 | E5: =(B5-C5)/C5 -> 0.016093739 | F5: =_xlfn.XLOOKUP(A5,Table!A:A, Table!G:G) -> 431.42
A6: 42446 | B6: =_xlfn.XLOOKUP(A6,Table!A:A, Table!C:C) -> 571.4 | C6: =_xlfn.XLOOKUP(A6,Table!A:A, Table!D:D) -> 555.01 | D6: =B6-C6 -> 16.39 | E6: =(B6-C6)/C6 -> 0.029530999 | F6: =_xlfn.XLOOKUP(A6,Table!A:A, Table!G:G) -> 559.44 | G6: =_xlfn.XLOOKUP(A9, Table!A:A, Table!G:G) -> 574.27 | H6: =F6-G6 -> -14.83
A7: 41796
C8: #3a. | D8: #4a. | F8: #5
A9: 42445 | C9: =_xlfn.XLOOKUP(A6, Table!A:A, Table!J:J) -> -14.83 | D9: =_xlfn.XLOOKUP(A7, Table!A:A, Table!K:K) -> 0.01885218 | F9: Daily Range | G9: Daily Range % | H9: Daily Change | I9: Daily Change %
E10: Largest | F10: =MAX(Table!H:H) -> 85.99 | G10: =MAX(Table!I:I) -> 0.33328202 | H10: =MAX(Table!J:J) -> 128.52 | I10: =MAX(Table!K:K) -> 0.34471366
A11: Average Growth Rate | F11: =_xlfn.XLOOKUP(F10,Table!H:H, Table!$A:$A) -> 42895 | G11: =_xlfn.XLOOKUP(G10,Table!I:I, Table!$A:$A) -> 36039 | H11: =_xlfn.XLOOKUP(H10,Table!J:J, Table!$A:$A) -> 43035 | I11: =_xlfn.XLOOKUP(I10,Table!K:K, Table!$A:$A) -> 37221
A12: Present Value, P | B12: 3480 | C12: 9971.25 | E12: Smallest | F12: =MIN(Table!H:H) -> 0.12 | G12: =MIN(Table!I:I) -> 0.0037501176 | H12: =MIN(Table!J:J) -> -48.35 | I12: =MIN(Table!K:K) -> -0.24766064
A13: Future Value, f(t) | B13: 4242.1 | C13: 25784.96 | F13: =_xlfn.XLOOKUP(F12,Table!H:H, Table!$A:$A) -> 35607 | G13: =_xlfn.XLOOKUP(G12,Table!I:I, Table!$A:$A) -> 42811 | H13: =_xlfn.XLOOKUP(H12,Table!J:J, Table!$A:$A) -> 42398 | I13: =_xlfn.XLOOKUP(I12,Table!K:K, Table!$A:$A) -> 37096
A14: time (years), t | B14: 10 | C14: 3.5
A15: CAGR, r | B15: =(B13/B12)^(1/B14)-1 -> 0.019999986 | C15: =(C13/C12)^(1/C14)-1 -> 0.31186918 | F15: 20000
A16: Xlookup | F16: =F15+F15*0.025 -> 20500 | H16: #6, #7, #8,#9
A17: Find the Close and Adj. Close on 12/22/14 | F17: =F16+F16*0.025 -> 21012.5 | H17: Criteria | I17: # of days | J17: %
A18: Date | B18: Close | C18: Adj.Close | F18: =F17+F17*0.025 -> 21537.812 | H18: <0 | I18: =COUNTIF(Table!K:K, H18) -> 2539 | J18: =I18/I21 -> 0.49195892
A19: 41995 | B19: =_xlfn.XLOOKUP(A19,Table!A:A,Table!E:E) -> 306.54 | C19: =_xlfn.XLOOKUP(A19,Table!A:A, Table!G:G ) -> 306.54 | F19: =F18+F18*0.025 -> 22076.258 | H19: >0 | I19: =COUNTIF(Table!K:K, H19) -> 2587 | J19: =I19/I21 -> 0.50125945
F20: =F19+F19*0.025 -> 22628.164 | H20: >=2.00% | I20: =COUNTIF(Table!K:K, $H$20) -> 1055 | J20: =I20/I21 -> 0.20441775
A21: Find all data for the given date. | H21: >2.00% | I21: 5161 | J21: =J19+J18 -> 0.99321837
A22: Date | B22: Open | C22: High | D22: Low | E22: Close | F22: Volume | G22: Adj.Close | H22: < 8000000 | I22: =COUNTIFS(Table!K:K, H21, Table!F:F, H22) -> 488 | J22: =I22/I21 -> 0.094555319
A23: 41995 | B23: {=_xlfn.XLOOKUP(A23,Table!A:A, Table!B:G)} -> 301.94 | C23: 307.36 | D23: 301.94 | E23: 306.54 | F23: 4003800 | G23: 306.54
A24: 4/23/
A26: Percent Change | H26: Part 3
A27: (New-Old)/Old | H27: #1-#4
C28: =2.48- (2.48*0.1009) -> 2.229768 | G28: Date | H28: Adjustment ratio | I28: Adj High | J28: Adj. Low
A29: =(1.19-1.683)/1.683 -> -0.29292929 | G29: 36395 | H29: =_xlfn.XLOOKUP(G29, Table!A:A, Table!L:L) -> 0.5
A30: =(66-54)/54 -> 0.22222222 | G30: 36896 | H30: =_xlfn.XLOOKUP(G30, Table!A:A, Table!L:L) -> 1
B31: Round, Rounddown, and Roundup | E31: Int | G31: 42433 | H31: =_xlfn.XLOOKUP(G31, Table!A:A, Table!L:L) -> 1
A32: Number | B32: Whole | C32: Nereast cent | G32: 35663 | I32: =_xlfn.XLOOKUP(G32, Table!A:A, Table!M:M) -> 2.1698582
A33: 2.67 | B33: =ROUND(A33,0) -> 3 | C33: =ROUND(A33,2) -> 2.67 | E33: =INT(A33) -> 2 | G33: 36348 | I33: =_xlfn.XLOOKUP(G33, Table!A:A, Table!M:M) -> 63.75
A34: 7.8949 | B34: =ROUND(A34,0) -> 8 | C34: =ROUND(A34,2) -> 7.89
A35: 13.7 | B35: =ROUND(A35,0) -> 14 | C35: =ROUND(A35,2) -> 13.7
A36: 15.2229 | B36: =ROUND(A36,0) -> 15 | C36: =ROUND(A36,2) -> 15.22 | G36: Homework #2
F37: Criteria | G37: Date
A38: "Tuition costs were 24.97% higher in 2020 compared to 2015. In 2020 the tuition cost was $10,502. What was the tuition cost in 2015?" | G38: 42880 | H38: =_xlfn.XLOOKUP(G38,Table!A:A, Table!I:I) -> 0.017197666
A39: =10502/1.2497 -> 8403.6169 | B39: <-Answer | G39: 42821 | H39: =_xlfn.XLOOKUP(G39, Table!A:A, Table!J:J) -> 1.21
F40: >4.58% | H40: =COUNTIF(Table!$K:$K, F40) -> 386
F41: <3.368 | H41: =COUNTIF(Table!H:H, F41) -> 2558
...
