Workbook

Sheet Price and Cost
B1: Price
B2: Wholesale Price | C2: 0.35 | D2: per unit
B3: This is the amount that the company making the product receives from the retail stores that will sell it to consumers.
B5: Per Unit Cost
B6: For the first | C6: 500000 | D6: units annually, the cost is | E6: 0.21 | F6: per unit
D7: For additional units in a year, the cost is | E7: 0.13 | F7: per unit
B9: Year 1 | C9: 2 | D9: 3 | E9: 4 | F9: 5 | G9: 6 | H9: 7 | I9: 8 | J9: 9 | K9: 10
A10: Total Units | B10: ='Overall Financial Model'!B4 -> 280000 | C10: ='Overall Financial Model'!C4 -> 697500 | D10: ='Overall Financial Model'!D4 -> 760275 | E10: ='Overall Financial Model'!E4 -> 828699.75 | F10: ='Overall Financial Model'!F4 -> 903282.73 | G10: ='Overall Financial Model'!G4 -> 984578.17 | H10: ='Overall Financial Model'!H4 -> 1073190.2 | I10: ='Overall Financial Model'!I4 -> 1169777.3 | ... K10: ='Overall Financial Model'!K4 -> 1389812.4 | L10: 2
A12: <500000 | B12: =B10*E6 -> 58800 | C12: =$C6*$E6 -> 105000 | D12: =$C6*$E6 -> 105000 | E12: =$C6*$E6 -> 105000 | F12: =$C6*$E6 -> 105000 | G12: =$C6*$E6 -> 105000 | H12: =$C6*$E6 -> 105000 | I12: =$C6*$E6 -> 105000 | J12: =$C6*$E6 -> 105000 | K12: =$C6*$E6 -> 105000
A13: >500000 | C13: =(C10-$C6)*$E7 -> 25675 | D13: =(D10-$C6)*$E7 -> 33835.75 | E13: =(E10-$C6)*$E7 -> 42730.968 | F13: =(F10-$C6)*$E7 -> 52426.755 | G13: =(G10-$C6)*$E7 -> 62995.162 | H13: =(H10-$C6)*$E7 -> 74514.727 | I13: =(I10-$C6)*$E7 -> 87071.053 | J13: =(J10-$C6)*$E7 -> 100757.45 | K13: =(K10-$C6)*$E7 -> 115675.62
A14: Cost of Goods | B14: =B12 -> 58800 | C14: =SUM(C12:C13) -> 130675 | D14: =SUM(D12:D13) -> 138835.75 | E14: =SUM(E12:E13) -> 147730.97 | F14: =SUM(F12:F13) -> 157426.75 | G14: =SUM(G12:G13) -> 167995.16 | H14: =SUM(H12:H13) -> 179514.73 | I14: =SUM(I12:I13) -> 192071.05 | J14: =SUM(J12:J13) -> 205757.45 | K14: =SUM(K12:K13) -> 220675.62
B18: lower | C18: Upper | D18: Per unit cost
B19: 0 | C19: 500000 | D19: 0.21
B20: 500000 | C20: No limit | D20: 0.13
A22: Total units | B22: Cost of goods | C22: Cost of goods other
A23: {=TRANSPOSE(B10:K10)} -> 280000 | B23: {=TRANSPOSE(B14:K14)} -> 58800 | C23: {=TRANSPOSE(B41:K41)} -> 86800 | D23: These are all wrong use below
A24: 697500 | B24: 130675 | C24: 194825
A25: 760275 | B25: 138835.75 | C25: 210136.25
A26: 828699.75 | B26: 147730.97 | C26: 234084.91
A27: 903282.73 | B27: 157426.75 | C27: 260188.95
A28: 984578.17 | B28: 167995.16 | C28: 288642.36
A29: 1073190.2 | B29: 179514.73 | C29: 319656.57 | E29: lower | F29: upper | G29: per unit cost
A30: 1169777.3 | B30: 192071.05 | C30: 353462.06 | E30: 0 | F30: 430000 | G30: 0.31
A31: 1275057.3 | B31: 205757.45 | C31: 390310.05 | E31: 430000 | F31: 753000 | G31: 0.23
A32: 1389812.4 | B32: 220675.62 | C32: 430474.35 | E32: 753000 | F32: no limit | G32: 0.12
A35: Total units | B35: =B10 -> 280000 | C35: =C10 -> 697500 | D35: =D10 -> 760275 | E35: =E10 -> 828699.75 | F35: =F10 -> 903282.73 | G35: =G10 -> 984578.17 | H35: =H10 -> 1073190.2 | I35: =I10 -> 1169777.3 | ... K35: =K10 -> 1389812.4
A37: <430,000 | B37: =B35*G30 -> 86800 | C37: =$F30*$G30 -> 133300 | D37: =$F30*$G30 -> 133300 | E37: =$F30*$G30 -> 133300 | F37: =$F30*$G30 -> 133300 | G37: =$F30*$G30 -> 133300 | H37: =$F30*$G30 -> 133300 | I37: =$F30*$G30 -> 133300 | J37: =$F30*$G30 -> 133300 | K37: =$F30*$G30 -> 133300
A38: 430000><753000 | C38: =(C35-$E31)*$G31 -> 61525 | D38: =(D35-$E31)*$G31 -> 75963.25 | E38: =(E35-$E31)*$G31 -> 91700.943 | F38: =(F35-$E31)*$G31 -> 108855.03 | G38: =(G35-$E31)*$G31 -> 127552.98 | H38: =(H35-$E31)*$G31 -> 147933.75 | I38: =(I35-$E31)*$G31 -> 170148.79 | J38: =(J35-$E31)*$G31 -> 194363.18 | K38: =(K35-$E31)*$G31 -> 220756.86
A39: <753000 | D39: =(D35-$E32)*$G32 -> 873 | E39: =(E35-$E32)*$G32 -> 9083.97 | F39: =(F35-$E32)*$G32 -> 18033.927 | G39: =(G35-$E32)*$G32 -> 27789.381 | H39: =(H35-$E32)*$G32 -> 38422.825 | I39: =(I35-$E32)*$G32 -> 50013.279 | J39: =(J35-$E32)*$G32 -> 62646.874 | K39: =(K35-$E32)*$G32 -> 76417.493
A41: cost of goods | B41: =SUM(B$37:B$39) -> 86800 | C41: =SUM(C$37:C$39) -> 194825 | D41: =SUM(D$37:D$39) -> 210136.25 | E41: =SUM(E$37:E$39) -> 234084.91 | F41: =SUM(F$37:F$39) -> 260188.95 | G41: =SUM(G$37:G$39) -> 288642.36 | H41: =SUM(H$37:H$39) -> 319656.57 | I41: =SUM(I$37:I$39) -> 353462.06 | ... K41: =SUM(K$37:K$39) -> 430474.35
A43: # of Units | B43: 903282.73
A44: Orriginal Cost sctructure | C44: Per Unit cost | D44: Units in bracket | E44: Sub Cost
A45: 0 | B45: 500000 | C45: 0.21 | D45: =IF(B43>B45, B45, B43) -> 500000 | E45: =D45*C45 -> 105000
A46: 500000 | B46: no limit | C46: 0.13 | D46: =IF(B43>A46, B43-A46, 0) -> 403282.73 | E46: =D46*C46 -> 52426.755
D47: Total Cost | E47: =SUM(E45:E46) -> 157426.75
A49: # of Units | B49: =B43 -> 903282.73 | F49: Difference
A50: New Cost Structure | C50: Per Unit Cost | D50: Units in Bracket | E50: Sub Cost | F50: =E47-E54 -> -68197.173
A51: 0 | B51: 430000 | C51: 0.31 | D51: =IF(B49>B51, B51, B49) -> 430000 | E51: =D51*C51 -> 133300
A52: 430000 | B52: 753000 | C52: 0.23 | D52: =IF(B49<B52, B49-B51,B52-B51) -> 323000 | E52: =D52*C52 -> 74290
A53: 753000 | B53: no limit | C53: 0.12 | D53: =IF(B49>A53, B49-A53, 0) -> 150282.73 | E53: =D53*C53 -> 18033.928
...

Sheet Units
A1: Model to Estimate Number of Units by Year
A3: Assumption | B3: 0.09 | C3: annual growth in number of stores from Year 2 to Year 3 and each year after, for all three channels
B6: Year | C6: Year | D6: Year | E6: Year | F6: Year | G6: Year | H6: Year
B7: 1 | C7: 2 | D7: 3 | E7: 4 | F7: 5 | G7: 6 | H7: 7 | I7: 8 | J7: 9 | K7: 10 | L7: 11 | M7: 12 | N7: 13
A8: Number of Stores by Channel
A9: Convenience Stores | B9: 35 | C9: 85 | D9: =C9*(1+$B$3) -> 92.65 | E9: =D9*(1+$B$3) -> 100.9885 | F9: =E9*(1+$B$3) -> 110.07747 | G9: =F9*(1+$B$3) -> 119.98444 | H9: =G9*(1+$B$3) -> 130.78304 | I9: =H9*(1+$B$3) -> 142.55351 | J9: =I9*(1+$B$3) -> 155.38333 | K9: =J9*(1+$B$3) -> 169.36782 | ... N9: =M9*(1+$B$3) -> 219.33624
A10: Grocery Stores | B10: 30 | C10: 65 | D10: =C10*(1+$B$3) -> 70.85 | E10: =D10*(1+$B$3) -> 77.2265 | F10: =E10*(1+$B$3) -> 84.176885 | G10: =F10*(1+$B$3) -> 91.752805 | H10: =G10*(1+$B$3) -> 100.01056 | I10: =H10*(1+$B$3) -> 109.01151 | J10: =I10*(1+$B$3) -> 118.82254 | K10: =J10*(1+$B$3) -> 129.51657 | ... N10: =M10*(1+$B$3) -> 167.72772
A11: Mass Stores | B11: 5 | C11: 25 | D11: =C11*(1+$B$3) -> 27.25 | E11: =D11*(1+$B$3) -> 29.7025 | F11: =E11*(1+$B$3) -> 32.375725 | G11: =F11*(1+$B$3) -> 35.28954 | H11: =G11*(1+$B$3) -> 38.465599 | I11: =H11*(1+$B$3) -> 41.927503 | J11: =I11*(1+$B$3) -> 45.700978 | K11: =J11*(1+$B$3) -> 49.814066 | ... N11: =M11*(1+$B$3) -> 64.51066
A13: Units by Channel | O13: Annual Units per Store by Channel
A14: Convenience Stores | B14: =B9*$O14 -> 157500 | C14: =C9*$O14 -> 382500 | D14: =D9*$O14 -> 416925 | E14: =E9*$O14 -> 454448.25 | F14: =F9*$O14 -> 495348.59 | G14: =G9*$O14 -> 539929.97 | H14: =H9*$O14 -> 588523.66 | I14: =I9*$O14 -> 641490.79 | ... N14: =N9*$O14 -> 987013.1 | O14: 4500
A15: Grocery Stores | B15: =B10*$O15 -> 105000 | C15: =C10*$O15 -> 227500 | D15: =D10*$O15 -> 247975 | E15: =E10*$O15 -> 270292.75 | F15: =F10*$O15 -> 294619.1 | G15: =G10*$O15 -> 321134.82 | H15: =H10*$O15 -> 350036.95 | I15: =I10*$O15 -> 381540.28 | ... N15: =N10*$O15 -> 587047.01 | O15: 3500
A16: Mass Stores | B16: =B11*$O16 -> 17500 | C16: =C11*$O16 -> 87500 | D16: =D11*$O16 -> 95375 | E16: =E11*$O16 -> 103958.75 | F16: =F11*$O16 -> 113315.04 | G16: =G11*$O16 -> 123513.39 | H16: =H11*$O16 -> 134629.6 | I16: =I11*$O16 -> 146746.26 | ... N16: =N11*$O16 -> 225787.31 | O16: 3500
A18: Total Units Across the Three Channels | B18: =SUM(B$14:B$16) -> 280000 | C18: =SUM(C$14:C$16) -> 697500 | D18: =SUM(D$14:D$16) -> 760275 | E18: =SUM(E$14:E$16) -> 828699.75 | F18: =SUM(F$14:F$16) -> 903282.73 | G18: =SUM(G$14:G$16) -> 984578.17 | H18: =SUM(H$14:H$16) -> 1073190.2 | I18: =SUM(I$14:I$16) -> 1169777.3 | ... N18: =SUM(N$14:N$16) -> 1799847.4

Sheet Operating Costs
A1: Model to Estimate Operating Costs
A3: Assumption | B3: 0.05 | C3: annual growth in operating costs from Year 2 to Year 3 and each year after
B6: Year | C6: Year | D6: Year | E6: Year | F6: Year | G6: Year | H6: Year
B7: 1 | C7: 2 | D7: 3 | E7: 4 | F7: 5 | G7: 6 | H7: 7 | I7: 8 | J7: 9 | K7: 10
A8: Operating Costs Estimates | B8: 60000 | C8: 110000 | D8: =C8*(1+$B3) -> 115500 | E8: =D8*(1+$B3) -> 121275 | F8: =E8*(1+$B3) -> 127338.75 | G8: =F8*(1+$B3) -> 133705.69 | H8: =G8*(1+$B3) -> 140390.97 | I8: =H8*(1+$B3) -> 147410.52 | J8: =I8*(1+$B3) -> 154781.05 | K8: =J8*(1+$B3) -> 162520.1

Sheet Overall Financial Model
A1: Financial Model
B2: Year | C2: Year | D2: Year | E2: Year | F2: Year | G2: Year | H2: Year | I2: Year | J2: year | K2: Year
B3: 1 | C3: 2 | D3: 3 | E3: 4 | F3: 5 | G3: 6 | H3: 7 | I3: 8 | J3: 9 | K3: 10
A4: Total Units | B4: =Units!B18 -> 280000 | C4: =Units!C18 -> 697500 | D4: =Units!D18 -> 760275 | E4: =Units!E18 -> 828699.75 | F4: =Units!F18 -> 903282.73 | G4: =Units!G18 -> 984578.17 | H4: =Units!H18 -> 1073190.2 | I4: =Units!I18 -> 1169777.3 | ... K4: =Units!K18 -> 1389812.4
A5: Wholesale Price | B5: ='Price and Cost'!$C2 -> 0.35 | C5: ='Price and Cost'!$C2 -> 0.35 | D5: ='Price and Cost'!$C2 -> 0.35 | E5: ='Price and Cost'!$C2 -> 0.35 | F5: 0.39 | G5: ='Price and Cost'!$C2 -> 0.35 | H5: ='Price and Cost'!$C2 -> 0.35 | I5: ='Price and Cost'!$C2 -> 0.35 | J5: ='Price and Cost'!$C2 -> 0.35 | K5: ='Price and Cost'!$C2 -> 0.35
A7: Revenue | B7: =B4*B5 -> 98000 | C7: =C4*C5 -> 244125 | D7: =D4*D5 -> 266096.25 | E7: =E4*E5 -> 290044.91 | F7: =F4*F5 -> 352280.26 | G7: =G4*G5 -> 344602.36 | H7: =H4*H5 -> 375616.57 | I7: =I4*I5 -> 409422.06 | ... K7: =K4*K5 -> 486434.35
A8: Cost of Goods | B8: ='Price and Cost'!B14 -> 58800 | C8: ='Price and Cost'!C14 -> 130675 | D8: ='Price and Cost'!D14 -> 138835.75 | E8: ='Price and Cost'!E14 -> 147730.97 | F8: ='Price and Cost'!F14 -> 157426.75 | G8: ='Price and Cost'!G14 -> 167995.16 | H8: ='Price and Cost'!H14 -> 179514.73 | I8: ='Price and Cost'!I14 -> 192071.05 | ... K8: ='Price and Cost'!K14 -> 220675.62
A9: Operating Costs | B9: ='Operating Costs'!B8 -> 60000 | C9: ='Operating Costs'!C8 -> 110000 | D9: ='Operating Costs'!D8 -> 115500 | E9: ='Operating Costs'!E8 -> 121275 | F9: ='Operating Costs'!F8 -> 127338.75 | G9: ='Operating Costs'!G8 -> 133705.69 | H9: ='Operating Costs'!H8 -> 140390.97 | I9: ='Operating Costs'!I8 -> 147410.52 | ... K9: ='Operating Costs'!K8 -> 162520.1
A10: Operating Income (= Revenue-Cost of Goods-Operating Costs) | B10: =B7-B8-B9 -> -20800 | C10: =C7-C8-C9 -> 3450 | D10: =D7-D8-D9 -> 11760.5 | E10: =E7-E8-E9 -> 21038.945 | F10: =F7-F8-F9 -> 67514.759 | G10: =G7-G8-G9 -> 42901.511 | H10: =H7-H8-H9 -> 55710.874 | I10: =I7-I8-I9 -> 69940.492 | ... K10: =K7-K8-K9 -> 103238.64
F13: 67514.759
F14: 31383.45
F15: =F13-F14 -> 36131.309
H18: Probability | I18: Amount
G19: Base | H19: 0.6 | I19: 55711
G20: Pessimistic | H20: 0.2 | I20: =I19*0.65 -> 36212.15
G21: Optimistic | H21: 0.2 | I21: =I19*1.65 -> 91923.15
G22: Expected Value | I22: =SUMPRODUCT(H19:H21, I19:I21) -> 59053.66
