Workbook

Sheet concepts
A1: 1 | B1: Caffeinated chocolate bar. | C1: This product would be a regular size chocolate bar, similar in shape and size to the familiar 1.5 oz. Hershey, Nestle Crunch, or Dark Chocolate Fair Trade bars available by the checkout counter at a grocery store. The bar would be available in both milk and dark chocolate. The bar would have 3 or 4 easily separated pieces; each piece would have 100 mg of caffeine, the amount of caffeine in a regular cup of coffee.
A2: 2 | B2: Caffeinated cookies. | C2: Flavors available would include chocolate chip, oatmeal raisin, and peanut butter. The cookie would be a regular size, soft cookie, sold in a single-serving package or by the bundle. A cookie would have 100 mg of caffeine, the amount of caffeine in a regular cup of coffee.
A3: 3 | B3: Caffeinated chocolates. | C3: Caffeinated chocolate pieces, similar in size, but not necessarily shape, to a Hershey’s kiss. Three pieces would have about 100 mg of caffeine, the same caffeine as in a regular cup of coffee. They would be available in either milk or dark chocolate. There would be 6-10 pieces in a resealable package.
A4: 4 | B4: Caffeinated potato chips. | C4: Flavors would include regular salted, BBQ, Cheddar, Sour Cream and Onion, and others. The caffeine would be baked right into the chips. They would be sold in both individual serving size bags and larger family style bags. A large handful of chips would contain 100mg of caffeine, the same as in a regular cup of coffee.
A5: 5 | B5: Caffeinated water. | C5: Water would be tasteless and sold in various sizes including 12 oz bottles. A 12oz bottle would contain 100mg of caffeine, the same as a regular cup of coffee.
A6: 6 | B6: Caffeinated cereal/granola. | C6: Flavors would include a sweet cereal, whole grain cereal, and a granola. Cereal would be sold in traditional cereal boxes, and also available in snack size resealable pouches. A normal bowl size serving would have 100mg of caffeine, the same amount as a regular cup of coffee.
A7: 7 | B7: Caffeinated hamburger meat. | C7: Hamburger meat would be available in various fat contents including 85% lean, 90% lean and 95% lean. Hamburger meat would available in packages in supermarket meat sections. A single 1/2 pound burger serving would contain 100mg of caffeine, the same amount as a regular cup of coffee.

Sheet Sheet1
A1: Score | B1: Weight | C1: Product | E1: #s | F1: Average | G1: #'s | H1: Average | J1: #'s | K1: Frequency | L1: Total | M1: Average
A2: 75 | B2: 0.25 | C2: =A2*B2 -> 18.75 | E2: 227 | F2: =(E2+E3+E4+E5+E6+E7)/6 -> 282.33333 | G2: 71 | H2: =(G2+G3+G4+G5)/4 -> 74 | J2: 12 | K2: 10 | L2: =J2*K2 -> 120 | M2: =(L2+L3+L4+L5+L6+L7+L8)/M3 -> 15.286957
A3: 90 | B3: 0.2 | C3: =A3*B3 -> 18 | E3: 341 | G3: 69 | J3: 13 | K3: 17 | L3: =J3*K3 -> 221 | M3: =SUM(K2:K8) -> 115
A4: 93 | B4: 0.13 | C4: =A4*B4 -> 12.09 | E4: 168 | G4: 71 | J4: 14 | K4: 14 | L4: =J4*K4 -> 196
A5: 62.285714 | B5: 0.42 | C5: =A5*B5 -> 26.16 | E5: 500 | G5: 85 | J5: 15 | K5: 15 | L5: =J5*K5 -> 225
E6: 182 | J6: 16 | K6: 22 | L6: =J6*K6 -> 352
A7: Sum of (entries*weight) | B7: =C2+C3+C4+C5 -> 75 | E7: 276 | J7: 17 | K7: 22 | L7: =J7*K7 -> 374
A8: Sum of all weights | B8: =B2+B3+B4+B5 -> 1 | J8: 18 | K8: 15 | L8: =J8*K8 -> 270
A9: Weighted mean | B9: 80.6
A11: Purchase Intent
C12: Definitley would not | D12: Probably would not | E12: might or might not | F12: Probably would | G12: Definitley would | K12: Filters | L12: Gender | M12: Age LB | N12: Age UB | O12: Employment | P12: Low Quality
A13: # | B13: Concept Name | C13: 1 | D13: 2 | E13: 3 | F13: 4 | G13: 5 | H13: Number of Responses | I13: Average Purchase Intent
A14: 1 | B14: Caffeinated chocolate bar | C14: =COUNTIFS(DataT!12:12,C$13) -> 37 | D14: =COUNTIFS(DataT!12:12,D$13) -> 33 | E14: =COUNTIFS(DataT!12:12,E$13) -> 41 | F14: =COUNTIFS(DataT!12:12,F$13) -> 23 | G14: =COUNTIFS(DataT!12:12,G$13) -> 6 | H14: =SUM(C14:G14) -> 140 | I14: =((C$13*C14)+(D$13*D14)+(E$13*E14)+(F$13*F14)+(G$13*G14))/H14 -> 2.4857143 | K14: Criteria for count | L14: >=0 | M14: 0 | N14: 8 | O14: >=0 | P14: >=0
A15: 2 | B15: Caffeinated cookies | C15: =COUNTIFS(DataT!13:13,C$13) -> 60 | D15: =COUNTIFS(DataT!13:13,D$13) -> 51 | E15: =COUNTIFS(DataT!13:13,E$13) -> 22 | F15: =COUNTIFS(DataT!13:13,F$13) -> 7 | G15: =COUNTIFS(DataT!13:13,G$13) -> 2 | H15: =SUM(C15:G15) -> 142 | I15: =((C$13*C15)+(D$13*D15)+(E$13*E15)+(F$13*F15)+(G$13*G15))/H15 -> 1.8732394
A16: 3 | B16: Caffeinated chocolates | C16: =COUNTIFS(DataT!14:14,C$13) -> 30 | D16: =COUNTIFS(DataT!14:14,D$13) -> 41 | E16: =COUNTIFS(DataT!14:14,E$13) -> 38 | F16: =COUNTIFS(DataT!14:14,F$13) -> 22 | G16: =COUNTIFS(DataT!14:14,G$13) -> 9 | H16: =SUM(C16:G16) -> 140 | I16: =((C$13*C16)+(D$13*D16)+(E$13*E16)+(F$13*F16)+(G$13*G16))/H16 -> 2.5642857
A17: 4 | B17: Caffeinated potato chips | C17: =COUNTIFS(DataT!15:15,C$13) -> 102 | D17: =COUNTIFS(DataT!15:15,D$13) -> 25 | E17: =COUNTIFS(DataT!15:15,E$13) -> 9 | F17: =COUNTIFS(DataT!15:15,F$13) -> 4 | G17: =COUNTIFS(DataT!15:15,G$13) -> 1 | H17: =SUM(C17:G17) -> 141 | I17: =((C$13*C17)+(D$13*D17)+(E$13*E17)+(F$13*F17)+(G$13*G17))/H17 -> 1.4184397
A18: 5 | B18: Caffeinated water | C18: =COUNTIFS(DataT!16:16,C$13) -> 59 | D18: =COUNTIFS(DataT!16:16,D$13) -> 40 | E18: =COUNTIFS(DataT!16:16,E$13) -> 21 | F18: =COUNTIFS(DataT!16:16,F$13) -> 13 | G18: =COUNTIFS(DataT!16:16,G$13) -> 6 | H18: =SUM(C18:G18) -> 139 | I18: =((C$13*C18)+(D$13*D18)+(E$13*E18)+(F$13*F18)+(G$13*G18))/H18 -> 2.0431655
A19: 6 | B19: Caffeinated cereal/granola | C19: =COUNTIFS(DataT!17:17,C$13) -> 75 | D19: =COUNTIFS(DataT!17:17,D$13) -> 39 | E19: =COUNTIFS(DataT!17:17,E$13) -> 18 | F19: =COUNTIFS(DataT!17:17,F$13) -> 6 | G19: =COUNTIFS(DataT!17:17,G$13) -> 2 | H19: =SUM(C19:G19) -> 140 | I19: =((C$13*C19)+(D$13*D19)+(E$13*E19)+(F$13*F19)+(G$13*G19))/H19 -> 1.7214286
A20: 7 | B20: Caffeinated hamburger meat | C20: =COUNTIFS(DataT!18:18,C$13) -> 120 | D20: =COUNTIFS(DataT!18:18,D$13) -> 16 | E20: =COUNTIFS(DataT!18:18,E$13) -> 4 | F20: =COUNTIFS(DataT!18:18,F$13) -> 2 | G20: =COUNTIFS(DataT!18:18,G$13) -> 0 | H20: =SUM(C20:G20) -> 142 | I20: =((C$13*C20)+(D$13*D20)+(E$13*E20)+(F$13*F20)+(G$13*G20))/H20 -> 1.2112676
C21: Distrbution of Responses
C22: %1s | D22: %2s | E22: %3s | F22: %4s | G22: %5s | I22: Top 2 Box | J22: Purch Prob | K22: Other purch prob
A23: 1 | B23: Caffeinated chocolate bar | C23: =C14/$H14 -> 0.26428571 | D23: =D14/$H14 -> 0.23571429 | E23: =E14/$H14 -> 0.29285714 | F23: =F14/$H14 -> 0.16428571 | G23: =G14/$H14 -> 0.042857143 | H23: =H14/$H14 -> 1 | I23: =F23+G23 -> 0.20714286 | J23: =SUMPRODUCT(C23:G23, C$32:G$32) -> 0.37142857 | K23: =SUMPRODUCT(C23:G23, C$33:G$33) -> 0.29221429
A24: 2 | B24: Caffeinated cookies | C24: =C15/$H15 -> 0.42253521 | D24: =D15/$H15 -> 0.35915493 | E24: =E15/$H15 -> 0.15492958 | F24: =F15/$H15 -> 0.049295775 | G24: =G15/$H15 -> 0.014084507 | H24: =H15/$H15 -> 1 | I24: =F24+G24 -> 0.063380282 | J24: =SUMPRODUCT(C24:G24, C$32:G$32) -> 0.21830986 | K24: =SUMPRODUCT(C24:G24, C$33:G$33) -> 0.13112676
A25: 3 | B25: Caffeinated chocolates | C25: =C16/$H16 -> 0.21428571 | D25: =D16/$H16 -> 0.29285714 | E25: =E16/$H16 -> 0.27142857 | F25: =F16/$H16 -> 0.15714286 | G25: =G16/$H16 -> 0.064285714 | H25: =H16/$H16 -> 1 | I25: =F25+G25 -> 0.22142857 | J25: =SUMPRODUCT(C25:G25, C$32:G$32) -> 0.39107143 | K25: =SUMPRODUCT(C25:G25, C$33:G$33) -> 0.29121429
A26: 4 | B26: Caffeinated potato chips | C26: =C17/$H17 -> 0.72340426 | D26: =D17/$H17 -> 0.17730496 | E26: =E17/$H17 -> 0.063829787 | F26: =F17/$H17 -> 0.028368794 | G26: =G17/$H17 -> 0.0070921986 | H26: =H17/$H17 -> 1 | I26: =F26+G26 -> 0.035460993 | J26: =SUMPRODUCT(C26:G26, C$32:G$32) -> 0.10460993 | K26: =SUMPRODUCT(C26:G26, C$33:G$33) -> 0.060283688
A27: 5 | B27: Caffeinated water | C27: =C18/$H18 -> 0.42446043 | D27: =D18/$H18 -> 0.28776978 | E27: =E18/$H18 -> 0.15107914 | F27: =F18/$H18 -> 0.09352518 | G27: =G18/$H18 -> 0.043165468 | H27: =H18/$H18 -> 1 | I27: =F27+G27 -> 0.13669065 | J27: =SUMPRODUCT(C27:G27, C$32:G$32) -> 0.26079137 | K27: =SUMPRODUCT(C27:G27, C$33:G$33) -> 0.17302158
A28: 6 | B28: Caffeinated cereal/granola | C28: =C19/$H19 -> 0.53571429 | D28: =D19/$H19 -> 0.27857143 | E28: =E19/$H19 -> 0.12857143 | F28: =F19/$H19 -> 0.042857143 | G28: =G19/$H19 -> 0.014285714 | H28: =H19/$H19 -> 1 | I28: =F28+G28 -> 0.057142857 | J28: =SUMPRODUCT(C28:G28, C$32:G$32) -> 0.18035714 | K28: =SUMPRODUCT(C28:G28, C$33:G$33) -> 0.11128571
A29: 7 | B29: Caffeinated hamburger meat | C29: =C20/$H20 -> 0.84507042 | D29: =D20/$H20 -> 0.11267606 | E29: =E20/$H20 -> 0.028169014 | F29: =F20/$H20 -> 0.014084507 | G29: =G20/$H20 -> 0 | H29: =H20/$H20 -> 1 | I29: =F29+G29 -> 0.014084507 | J29: =SUMPRODUCT(C29:G29, C$32:G$32) -> 0.052816901 | K29: =SUMPRODUCT(C29:G29, C$33:G$33) -> 0.026197183
C31: 1 | D31: 2 | E31: 3 | F31: 4 | G31: 5
B32: Probaility | C32: 0 | D32: 0.25 | E32: 0.5 | F32: 0.75 | G32: 1
C33: 0 | D33: 0.02 | E33: 0.55 | F33: 0.6 | G33: 0.65
A34: Frequency
C35: Once a Month or less often | D35: More than once a month, but less than once a week | E35: 1 to 3 times a week
A36: # | B36: Concept Name | C36: 1 | D36: 2 | E36: 3 | F36: 4 | G36: 5 | H36: Number of Responses | I36: Average Purchase Intent
A37: 1 | B37: Caffeinated chocolate bar | C37: =COUNTIFS(DataT!26:26,C$36) -> 72 | D37: =COUNTIFS(DataT!26:26,D$36) -> 31 | E37: =COUNTIFS(DataT!26:26,E$36) -> 10 | F37: =COUNTIFS(DataT!26:26,F$36) -> 1 | G37: =COUNTIFS(DataT!26:26,G$36) -> 21 | H37: =SUM(C37:G37) -> 135 | I37: =((C$13*C37)+(D$13*D37)+(E$13*E37)+(F$13*F37)+(G$13*G37))/H37 -> 2.0222222
A38: 2 | B38: Caffeinated cookies | C38: =COUNTIFS(DataT!27:27,C$36) -> 84 | D38: =COUNTIFS(DataT!27:27,D$36) -> 14 | E38: =COUNTIFS(DataT!27:27,E$36) -> 4 | F38: =COUNTIFS(DataT!27:27,F$36) -> 2 | G38: =COUNTIFS(DataT!27:27,G$36) -> 32 | H38: =SUM(C38:G38) -> 136 | I38: =((C$13*C38)+(D$13*D38)+(E$13*E38)+(F$13*F38)+(G$13*G38))/H38 -> 2.1470588
A39: 3 | B39: Caffeinated chocolates | C39: =COUNTIFS(DataT!28:28,C$36) -> 77 | D39: =COUNTIFS(DataT!28:28,D$36) -> 24 | E39: =COUNTIFS(DataT!28:28,E$36) -> 15 | F39: =COUNTIFS(DataT!28:28,F$36) -> 3 | G39: =COUNTIFS(DataT!28:28,G$36) -> 15 | H39: =SUM(C39:G39) -> 134 | I39: =((C$13*C39)+(D$13*D39)+(E$13*E39)+(F$13*F39)+(G$13*G39))/H39 -> 1.9179104
A40: 4 | B40: Caffeinated potato chips | C40: =COUNTIFS(DataT!29:29,C$36) -> 84 | D40: =COUNTIFS(DataT!29:29,D$36) -> 7 | E40: =COUNTIFS(DataT!29:29,E$36) -> 1 | F40: =COUNTIFS(DataT!29:29,F$36) -> 2 | G40: =COUNTIFS(DataT!29:29,G$36) -> 40 | H40: =SUM(C40:G40) -> 134 | I40: =((C$13*C40)+(D$13*D40)+(E$13*E40)+(F$13*F40)+(G$13*G40))/H40 -> 2.3059701
A41: 5 | B41: Caffeinated water | C41: =COUNTIFS(DataT!30:30,C$36) -> 78 | D41: =COUNTIFS(DataT!30:30,D$36) -> 20 | E41: =COUNTIFS(DataT!30:30,E$36) -> 14 | F41: =COUNTIFS(DataT!30:30,F$36) -> 3 | G41: =COUNTIFS(DataT!30:30,G$36) -> 20 | H41: =SUM(C41:G41) -> 135 | I41: =((C$13*C41)+(D$13*D41)+(E$13*E41)+(F$13*F41)+(G$13*G41))/H41 -> 2.0148148
A42: 6 | B42: Caffeinated cereal/granola | C42: =COUNTIFS(DataT!31:31,C$36) -> 81 | D42: =COUNTIFS(DataT!31:31,D$36) -> 17 | E42: =COUNTIFS(DataT!31:31,E$36) -> 5 | F42: =COUNTIFS(DataT!31:31,F$36) -> 2 | G42: =COUNTIFS(DataT!31:31,G$36) -> 28 | H42: =SUM(C42:G42) -> 133 | I42: =((C$13*C42)+(D$13*D42)+(E$13*E42)+(F$13*F42)+(G$13*G42))/H42 -> 2.0902256
...

Sheet Sheet2
A2: Filters | B2: Filters | C2: Filters | D2: Filters | E2: Filters | F2: Filters | G2: Filters | H2: Filters | I2: Filters
A5: Purchase Intent
C6: Definitley would not | D6: Probably would not | E6: might or might not | F6: Probably would | G6: Definitley would | K6: Filters | L6: Gender | M6: Age LB | N6: Age UB | O6: Employment
A7: # | B7: Concept Name | C7: 1 | D7: 2 | E7: 3 | F7: 4 | G7: 5 | H7: Number of Responses | I7: Average Purchase Intent | L7: >=0 | M7: 0 | N7: 8 | O7: 1
A8: 1 | B8: Caffeinated chocolate bar | C8: =COUNTIFS(DataT!12:12,C$7, DataT!$5:$5, $O$7) -> 4 | D8: =COUNTIFS(DataT!12:12,D$7, DataT!$5:$5, $O$7) -> 7 | E8: =COUNTIFS(DataT!12:12,E$7, DataT!$5:$5, $O$7) -> 8 | F8: =COUNTIFS(DataT!12:12,F$7, DataT!$5:$5, $O$7) -> 3 | G8: =COUNTIFS(DataT!12:12,G$7, DataT!$5:$5, $O$7) -> 1 | H8: =SUM(C8:G8) -> 23 | I8: =((C$7*C8)+(D$7*D8)+(E$7*E8)+(F$7*F8)+(G$7*G8))/H8 -> 2.5652174
A9: 2 | B9: Caffeinated cookies | C9: =COUNTIFS(DataT!13:13,C$7, DataT!$5:$5, $O$7) -> 11 | D9: =COUNTIFS(DataT!13:13,D$7, DataT!$5:$5, $O$7) -> 5 | E9: =COUNTIFS(DataT!13:13,E$7, DataT!$5:$5, $O$7) -> 4 | F9: =COUNTIFS(DataT!13:13,F$7, DataT!$5:$5, $O$7) -> 4 | G9: =COUNTIFS(DataT!13:13,G$7, DataT!$5:$5, $O$7) -> 0 | H9: =SUM(C9:G9) -> 24 | I9: =((C$7*C9)+(D$7*D9)+(E$7*E9)+(F$7*F9)+(G$7*G9))/H9 -> 2.0416667
A10: 3 | B10: Caffeinated chocolates | C10: =COUNTIFS(DataT!14:14,C$7, DataT!$5:$5, $O$7) -> 2 | D10: =COUNTIFS(DataT!14:14,D$7, DataT!$5:$5, $O$7) -> 7 | E10: =COUNTIFS(DataT!14:14,E$7, DataT!$5:$5, $O$7) -> 8 | F10: =COUNTIFS(DataT!14:14,F$7, DataT!$5:$5, $O$7) -> 4 | G10: =COUNTIFS(DataT!14:14,G$7, DataT!$5:$5, $O$7) -> 2 | H10: =SUM(C10:G10) -> 23 | I10: =((C$7*C10)+(D$7*D10)+(E$7*E10)+(F$7*F10)+(G$7*G10))/H10 -> 2.8695652
A11: 4 | B11: Caffeinated potato chips | C11: =COUNTIFS(DataT!15:15,C$7, DataT!$5:$5, $O$7) -> 18 | D11: =COUNTIFS(DataT!15:15,D$7, DataT!$5:$5, $O$7) -> 2 | E11: =COUNTIFS(DataT!15:15,E$7, DataT!$5:$5, $O$7) -> 2 | F11: =COUNTIFS(DataT!15:15,F$7, DataT!$5:$5, $O$7) -> 1 | G11: =COUNTIFS(DataT!15:15,G$7, DataT!$5:$5, $O$7) -> 0 | H11: =SUM(C11:G11) -> 23 | I11: =((C$7*C11)+(D$7*D11)+(E$7*E11)+(F$7*F11)+(G$7*G11))/H11 -> 1.3913043
A12: 5 | B12: Caffeinated water | C12: =COUNTIFS(DataT!16:16,C$7, DataT!$5:$5, $O$7) -> 12 | D12: =COUNTIFS(DataT!16:16,D$7, DataT!$5:$5, $O$7) -> 6 | E12: =COUNTIFS(DataT!16:16,E$7, DataT!$5:$5, $O$7) -> 3 | F12: =COUNTIFS(DataT!16:16,F$7, DataT!$5:$5, $O$7) -> 2 | G12: =COUNTIFS(DataT!16:16,G$7, DataT!$5:$5, $O$7) -> 0 | H12: =SUM(C12:G12) -> 23 | I12: =((C$7*C12)+(D$7*D12)+(E$7*E12)+(F$7*F12)+(G$7*G12))/H12 -> 1.7826087
A13: 6 | B13: Caffeinated cereal/granola | C13: =COUNTIFS(DataT!17:17,C$7, DataT!$5:$5, $O$7) -> 12 | D13: =COUNTIFS(DataT!17:17,D$7, DataT!$5:$5, $O$7) -> 8 | E13: =COUNTIFS(DataT!17:17,E$7, DataT!$5:$5, $O$7) -> 2 | F13: =COUNTIFS(DataT!17:17,F$7, DataT!$5:$5, $O$7) -> 1 | G13: =COUNTIFS(DataT!17:17,G$7, DataT!$5:$5, $O$7) -> 0 | H13: =SUM(C13:G13) -> 23 | I13: =((C$7*C13)+(D$7*D13)+(E$7*E13)+(F$7*F13)+(G$7*G13))/H13 -> 1.6521739
A14: 7 | B14: Caffeinated hamburger meat | C14: =COUNTIFS(DataT!18:18,C$7, DataT!$5:$5, $O$7) -> 20 | D14: =COUNTIFS(DataT!18:18,D$7, DataT!$5:$5, $O$7) -> 2 | E14: =COUNTIFS(DataT!18:18,E$7, DataT!$5:$5, $O$7) -> 0 | F14: =COUNTIFS(DataT!18:18,F$7, DataT!$5:$5, $O$7) -> 2 | G14: =COUNTIFS(DataT!18:18,G$7, DataT!$5:$5, $O$7) -> 0 | H14: =SUM(C14:G14) -> 24 | I14: =((C$7*C14)+(D$7*D14)+(E$7*E14)+(F$7*F14)+(G$7*G14))/H14 -> 1.3333333
C15: Distrbution of Responses
C16: %1s | D16: %2s | E16: %3s | F16: %4s | G16: %5s | I16: Top 2 Box | J16: Purch Prob | K16: Other purch prob
A17: 1 | B17: Caffeinated chocolate bar | C17: =C8/$H8 -> 0.17391304 | D17: =D8/$H8 -> 0.30434783 | E17: =E8/$H8 -> 0.34782609 | F17: =F8/$H8 -> 0.13043478 | G17: =G8/$H8 -> 0.043478261 | H17: =H8/$H8 -> 1 | I17: =F17+G17 -> 0.17391304 | J17: =SUMPRODUCT(C17:G17, C$32:G$32) -> 0.26086957 | K17: =SUMPRODUCT(C17:G17, C$33:G$33) -> 0.7826087
A18: 2 | B18: Caffeinated cookies | C18: =C9/$H9 -> 0.45833333 | D18: =D9/$H9 -> 0.20833333 | E18: =E9/$H9 -> 0.16666667 | F18: =F9/$H9 -> 0.16666667 | G18: =G9/$H9 -> 0 | H18: =H9/$H9 -> 1 | I18: =F18+G18 -> 0.16666667 | J18: =SUMPRODUCT(C18:G18, C$32:G$32) -> 0.33333333 | K18: =SUMPRODUCT(C18:G18, C$33:G$33) -> 0.875
A19: 3 | B19: Caffeinated chocolates | C19: =C10/$H10 -> 0.086956522 | D19: =D10/$H10 -> 0.30434783 | E19: =E10/$H10 -> 0.34782609 | F19: =F10/$H10 -> 0.17391304 | G19: =G10/$H10 -> 0.086956522 | H19: =H10/$H10 -> 1 | I19: =F19+G19 -> 0.26086957 | J19: =SUMPRODUCT(C19:G19, C$32:G$32) -> 0.34782609 | K19: =SUMPRODUCT(C19:G19, C$33:G$33) -> 0.69565217
A20: 4 | B20: Caffeinated potato chips | C20: =C11/$H11 -> 0.7826087 | D20: =D11/$H11 -> 0.086956522 | E20: =E11/$H11 -> 0.086956522 | F20: =F11/$H11 -> 0.043478261 | G20: =G11/$H11 -> 0 | H20: =H11/$H11 -> 1 | I20: =F20+G20 -> 0.043478261 | J20: =SUMPRODUCT(C20:G20, C$32:G$32) -> 0.086956522 | K20: =SUMPRODUCT(C20:G20, C$33:G$33) -> 0.95652174
A21: 5 | B21: Caffeinated water | C21: =C12/$H12 -> 0.52173913 | D21: =D12/$H12 -> 0.26086957 | E21: =E12/$H12 -> 0.13043478 | F21: =F12/$H12 -> 0.086956522 | G21: =G12/$H12 -> 0 | H21: =H12/$H12 -> 1 | I21: =F21+G21 -> 0.086956522 | J21: =SUMPRODUCT(C21:G21, C$32:G$32) -> 0.17391304 | K21: =SUMPRODUCT(C21:G21, C$33:G$33) -> 1.0434783
A22: 6 | B22: Caffeinated cereal/granola | C22: =C13/$H13 -> 0.52173913 | D22: =D13/$H13 -> 0.34782609 | E22: =E13/$H13 -> 0.086956522 | F22: =F13/$H13 -> 0.043478261 | G22: =G13/$H13 -> 0 | H22: =H13/$H13 -> 1 | I22: =F22+G22 -> 0.043478261 | J22: =SUMPRODUCT(C22:G22, C$32:G$32) -> 0.086956522 | K22: =SUMPRODUCT(C22:G22, C$33:G$33) -> 1.2173913
A23: 7 | B23: Caffeinated hamburger meat | C23: =C14/$H14 -> 0.83333333 | D23: =D14/$H14 -> 0.083333333 | E23: =E14/$H14 -> 0 | F23: =F14/$H14 -> 0.083333333 | G23: =G14/$H14 -> 0 | H23: =H14/$H14 -> 1 | I23: =F23+G23 -> 0.083333333 | J23: =SUMPRODUCT(C23:G23, C$32:G$32) -> 0.16666667 | K23: =SUMPRODUCT(C23:G23, C$33:G$33) -> 1
C25: 1 | D25: 2 | E25: 3 | F25: 4 | G25: 5
B26: Probaility | C26: 0 | D26: 0.25 | E26: 0.5 | F26: 0.75 | G26: 1
C27: 0 | D27: 0.02 | E27: 0.55 | F27: 0.6 | G27: 0.65
A29: Purchase Intent
C30: Definitley would not | D30: Probably would not | E30: might or might not | F30: Probably would | G30: Definitley would | K30: Filters | L30: Gender | M30: Age LB | N30: Age UB
A31: # | B31: Concept Name | C31: 1 | D31: 2 | E31: 3 | F31: 4 | G31: 5 | H31: Number of Responses | I31: Average Purchase Intent | L31: >=0 | M31: 0 | N31: 8
A32: 1 | B32: Caffeinated chocolate bar | C32: =COUNTIFS(DataT!12:12, C$31, DataT!$18:$18, $K$33, DataT!$68:$68,$L$33 ) -> 0 | D32: =COUNTIFS(DataT!12:12, D$31, DataT!$18:$18, $K$33, DataT!$68:$68,$L$33 ) -> 0 | E32: =COUNTIFS(DataT!12:12, E$31, DataT!$18:$18, $K$33, DataT!$68:$68,$L$33 ) -> 0 | F32: =COUNTIFS(DataT!12:12, F$31, DataT!$18:$18, $K$33, DataT!$68:$68,$L$33 ) -> 2 | G32: =COUNTIFS(DataT!12:12, G$31, DataT!$18:$18, $K$33, DataT!$68:$68,$L$33 ) -> 0 | H32: =SUM(C32:G32) -> 2 | I32: =((C$7*C32)+(D$7*D32)+(E$7*E32)+(F$7*F32)+(G$7*G32))/H32 -> 4 | K32: Low Quality responses
A33: 2 | B33: Caffeinated cookies | C33: =COUNTIFS(DataT!13:13, C$31, DataT!$18:$18, $K$33, DataT!$68:$68,$L$33 ) -> 1 | D33: =COUNTIFS(DataT!13:13, D$31, DataT!$18:$18, $K$33, DataT!$68:$68,$L$33 ) -> 2 | E33: =COUNTIFS(DataT!13:13, E$31, DataT!$18:$18, $K$33, DataT!$68:$68,$L$33 ) -> 0 | F33: =COUNTIFS(DataT!13:13, F$31, DataT!$18:$18, $K$33, DataT!$68:$68,$L$33 ) -> 0 | G33: =COUNTIFS(DataT!13:13, G$31, DataT!$18:$18, $K$33, DataT!$68:$68,$L$33 ) -> 0 | H33: =SUM(C33:G33) -> 3 | I33: =((C$7*C33)+(D$7*D33)+(E$7*E33)+(F$7*F33)+(G$7*G33))/H33 -> 1.6666667 | K33: >=2 | L33: >0
A34: 3 | B34: Caffeinated chocolates | C34: =COUNTIFS(DataT!14:14, C$31, DataT!$18:$18, $K$33, DataT!$68:$68,$L$33 ) -> 0 | D34: =COUNTIFS(DataT!14:14, D$31, DataT!$18:$18, $K$33, DataT!$68:$68,$L$33 ) -> 0 | E34: =COUNTIFS(DataT!14:14, E$31, DataT!$18:$18, $K$33, DataT!$68:$68,$L$33 ) -> 1 | F34: =COUNTIFS(DataT!14:14, F$31, DataT!$18:$18, $K$33, DataT!$68:$68,$L$33 ) -> 0 | G34: =COUNTIFS(DataT!14:14, G$31, DataT!$18:$18, $K$33, DataT!$68:$68,$L$33 ) -> 1 | H34: =SUM(C34:G34) -> 2 | I34: =((C$7*C34)+(D$7*D34)+(E$7*E34)+(F$7*F34)+(G$7*G34))/H34 -> 4
A35: 4 | B35: Caffeinated potato chips | C35: =COUNTIFS(DataT!15:15, C$31, DataT!$18:$18, $K$33, DataT!$68:$68,$L$33 ) -> 0 | D35: =COUNTIFS(DataT!15:15, D$31, DataT!$18:$18, $K$33, DataT!$68:$68,$L$33 ) -> 0 | E35: =COUNTIFS(DataT!15:15, E$31, DataT!$18:$18, $K$33, DataT!$68:$68,$L$33 ) -> 1 | F35: =COUNTIFS(DataT!15:15, F$31, DataT!$18:$18, $K$33, DataT!$68:$68,$L$33 ) -> 0 | G35: =COUNTIFS(DataT!15:15, G$31, DataT!$18:$18, $K$33, DataT!$68:$68,$L$33 ) -> 0 | H35: =SUM(C35:G35) -> 1 | I35: =((C$7*C35)+(D$7*D35)+(E$7*E35)+(F$7*F35)+(G$7*G35))/H35 -> 3
A36: 5 | B36: Caffeinated water | C36: =COUNTIFS(DataT!16:16, C$31, DataT!$18:$18, $K$33, DataT!$68:$68,$L$33 ) -> 0 | D36: =COUNTIFS(DataT!16:16, D$31, DataT!$18:$18, $K$33, DataT!$68:$68,$L$33 ) -> 0 | E36: =COUNTIFS(DataT!16:16, E$31, DataT!$18:$18, $K$33, DataT!$68:$68,$L$33 ) -> 0 | F36: =COUNTIFS(DataT!16:16, F$31, DataT!$18:$18, $K$33, DataT!$68:$68,$L$33 ) -> 0 | G36: =COUNTIFS(DataT!16:16, G$31, DataT!$18:$18, $K$33, DataT!$68:$68,$L$33 ) -> 1 | H36: =SUM(C36:G36) -> 1 | I36: =((C$7*C36)+(D$7*D36)+(E$7*E36)+(F$7*F36)+(G$7*G36))/H36 -> 5
A37: 6 | B37: Caffeinated cereal/granola | C37: =COUNTIFS(DataT!17:17, C$31, DataT!$18:$18, $K$33, DataT!$68:$68,$L$33 ) -> 0 | D37: =COUNTIFS(DataT!17:17, D$31, DataT!$18:$18, $K$33, DataT!$68:$68,$L$33 ) -> 1 | E37: =COUNTIFS(DataT!17:17, E$31, DataT!$18:$18, $K$33, DataT!$68:$68,$L$33 ) -> 1 | F37: =COUNTIFS(DataT!17:17, F$31, DataT!$18:$18, $K$33, DataT!$68:$68,$L$33 ) -> 0 | G37: =COUNTIFS(DataT!17:17, G$31, DataT!$18:$18, $K$33, DataT!$68:$68,$L$33 ) -> 0 | H37: =SUM(C37:G37) -> 2 | I37: =((C$7*C37)+(D$7*D37)+(E$7*E37)+(F$7*F37)+(G$7*G37))/H37 -> 2.5
A38: 7 | B38: Caffeinated hamburger meat | C38: =COUNTIFS(DataT!18:18, C$31, DataT!$18:$18, $K$33, DataT!$68:$68,$L$33 ) -> 0 | D38: =COUNTIFS(DataT!18:18, D$31, DataT!$18:$18, $K$33, DataT!$68:$68,$L$33 ) -> 1 | E38: =COUNTIFS(DataT!18:18, E$31, DataT!$18:$18, $K$33, DataT!$68:$68,$L$33 ) -> 2 | F38: =COUNTIFS(DataT!18:18, F$31, DataT!$18:$18, $K$33, DataT!$68:$68,$L$33 ) -> 1 | G38: =COUNTIFS(DataT!18:18, G$31, DataT!$18:$18, $K$33, DataT!$68:$68,$L$33 ) -> 0 | H38: =SUM(C38:G38) -> 4 | I38: =((C$7*C38)+(D$7*D38)+(E$7*E38)+(F$7*F38)+(G$7*G38))/H38 -> 3
C39: Distrbution of Responses
C40: %1s | D40: %2s | E40: %3s | F40: %4s | G40: %5s | I40: Top 2 Box | J40: Purch Prob | K40: Other purch prob
A41: 1 | B41: Caffeinated chocolate bar | C41: =C32/$H32 -> 0 | D41: =D32/$H32 -> 0 | E41: =E32/$H32 -> 0 | F41: =F32/$H32 -> 1 | G41: =G32/$H32 -> 0 | H41: =H32/$H32 -> 1 | I41: =F41+G41 -> 1 | J41: =SUMPRODUCT(C41:G41, C$32:G$32) -> 2 | K41: =SUMPRODUCT(C41:G41, C$33:G$33) -> 0
A42: 2 | B42: Caffeinated cookies | C42: =C33/$H33 -> 0.33333333 | D42: =D33/$H33 -> 0.66666667 | E42: =E33/$H33 -> 0 | F42: =F33/$H33 -> 0 | G42: =G33/$H33 -> 0 | H42: =H33/$H33 -> 1 | I42: =F42+G42 -> 0 | J42: =SUMPRODUCT(C42:G42, C$32:G$32) -> 0 | K42: =SUMPRODUCT(C42:G42, C$33:G$33) -> 1.6666667
A43: 3 | B43: Caffeinated chocolates | C43: =C34/$H34 -> 0 | D43: =D34/$H34 -> 0 | E43: =E34/$H34 -> 0.5 | F43: =F34/$H34 -> 0 | G43: =G34/$H34 -> 0.5 | H43: =H34/$H34 -> 1 | I43: =F43+G43 -> 0.5 | J43: =SUMPRODUCT(C43:G43, C$32:G$32) -> 0 | K43: =SUMPRODUCT(C43:G43, C$33:G$33) -> 0
A44: 4 | B44: Caffeinated potato chips | C44: =C35/$H35 -> 0 | D44: =D35/$H35 -> 0 | E44: =E35/$H35 -> 1 | F44: =F35/$H35 -> 0 | G44: =G35/$H35 -> 0 | H44: =H35/$H35 -> 1 | I44: =F44+G44 -> 0 | J44: =SUMPRODUCT(C44:G44, C$32:G$32) -> 0 | K44: =SUMPRODUCT(C44:G44, C$33:G$33) -> 0
A45: 5 | B45: Caffeinated water | C45: =C36/$H36 -> 0 | D45: =D36/$H36 -> 0 | E45: =E36/$H36 -> 0 | F45: =F36/$H36 -> 0 | G45: =G36/$H36 -> 1 | H45: =H36/$H36 -> 1 | I45: =F45+G45 -> 1 | J45: =SUMPRODUCT(C45:G45, C$32:G$32) -> 0 | K45: =SUMPRODUCT(C45:G45, C$33:G$33) -> 0
...

Sheet response codes
A1: Column Label | B1: Question Wording
A2: GEN | B2: Your gender?
C3: Responses
C4: 1 | D4: Male
C5: 2 | D5: Female
A7: AGE | B7: Your age?
C8: Responses
C9: 1 | D9: Under 18
C10: 2 | D10: 18-25
C11: 3 | D11: 26-35
C12: 4 | D12: 36-45
C13: 5 | D13: 46-55
C14: 6 | D14: 56-65
C15: 7 | D15: 66-75
C16: 8 | D16: Over 75
A18: EMP | B18: Employment status?
C19: Responses
C20: 1 | D20: Student
C21: 2 | D21: Work part time
C22: 3 | D22: Work full time
C23: 4 | D23: Unemployed
A26: INTENT | B26: Based on the description, how likely would you be to purchase this product?
C27: Responses
C28: 1 | D28: Definitely would not purchase
C29: 2 | D29: Probably would not purchase
C30: 3 | D30: Might or might not purchase
C31: 4 | D31: Probably would purchase
C32: 5 | D32: Definitely would purchase
A34: UNIQ | B34: How different is this product from other products on the market today?
C35: Responses
C36: 1 | D36: There is nothing else like it.
C37: 2 | D37: There are other products that are something like this.
C38: 3 | D38: There are other products that are just like this.
C39: 4 | D39: There are a lot of other products that are just like this.
C40: 5 | D40: Don't know
A42: FREQ | B42: If you tried this product and it met your expectations for taste and effectiveness, how often could you see yourself using it?
C43: Responses
C44: 1 | D44: Once a month or less often
C45: 2 | D45: More than once a month but less than once a week
C46: 3 | D46: 1 to 3 times a week
...

Sheet Data
A1: V1 | B1: V10 | C1: GEN | D1: AGE | E1: EMP | F1: CUR-USE_1 | G1: CUR-USE_2 | H1: CUR-USE_3 | I1: CUR-USE_4 | J1: CUR-USE_5 | K1: Q16 | L1: INTENT(1) | M1: INTENT(2) | N1: INTENT(3) | O1: INTENT(4) | P1: INTENT(5) | Q1: INTENT(6) | R1: INTENT(7) | S1: UNIQ(1) | T1: UNIQ(2) | U1: UNIQ(3) | V1: UNIQ(4) | W1: UNIQ(5) | X1: UNIQ(6) | Y1: UNIQ(7) | Z1: FREQ(1) | AA1: FREQ(2) | AB1: FREQ(3) | AC1: FREQ(4) | AD1: FREQ(5) | AE1: FREQ(6) | AF1: FREQ(7) | AG1: SUB_1(1) | AH1: SUB_2(1) | AI1: SUB_3(1) | AJ1: SUB_4(1) | AK1: SUB_5(1) | AL1: SUB_1(2) | AM1: SUB_2(2) | AN1: SUB_3(2) | AO1: SUB_4(2) | AP1: SUB_5(2) | AQ1: SUB_1(3) | AR1: SUB_2(3) | AS1: SUB_3(3) | AT1: SUB_4(3) | AU1: SUB_5(3) | AV1: SUB_1(4) | AW1: SUB_2(4) | AX1: SUB_3(4) | AY1: SUB_4(4) | AZ1: SUB_5(4) | BA1: SUB_1(5) | BB1: SUB_2(5) | BC1: SUB_3(5) | BD1: SUB_4(5) | BE1: SUB_5(5) | BF1: SUB_1(6) | BG1: SUB_2(6) | BH1: SUB_3(6) | BI1: SUB_4(6) | BJ1: SUB_5(6) | BK1: SUB_1(7) | BL1: SUB_2(7) | BM1: SUB_3(7) | BN1: SUB_4(7) | BO1: SUB_5(7)
A2: ResponseID | B2: Finished | C2: Background questions / / Your gender? | D2: Your age? | E2: Employment status? | F2: Rate your consumption for each of the following products:-Regular coffee or espresso, latte, cappuccino, etc (not decaffeinated) | G2: Rate your consumption for each of the following products:-Caffeinated soda (examples: Coke, Pepsi, Mountain Dew) | H2: Rate your consumption for each of the following products:-Any brand of caffeinated energy drink (examples: Monster, Rockstar, Red Bull) | I2: Rate your consumption for each of the following products:-Any brand of energy shots (example: 5-hr energy) | J2: Rate your consumption for each of the following products:-Any brand of energy bars (example: PowerBar, LunaBar, Clif Bar) | K2: On each of the following pages, you will see a short description of a new product concept for a food... | L2: ${lm://Field/1} / / ${lm://Field/2} / / / / Based on the description, how likely would you be to purchase... (1) | M2: ${lm://Field/1} / / ${lm://Field/2} / / / / Based on the description, how likely would you be to purchase... (2) | N2: ${lm://Field/1} / / ${lm://Field/2} / / / / Based on the description, how likely would you be to purchase... (3) | O2: ${lm://Field/1} / / ${lm://Field/2} / / / / Based on the description, how likely would you be to purchase... (4) | P2: ${lm://Field/1} / / ${lm://Field/2} / / / / Based on the description, how likely would you be to purchase... (5) | Q2: ${lm://Field/1} / / ${lm://Field/2} / / / / Based on the description, how likely would you be to purchase... (6) | R2: ${lm://Field/1} / / ${lm://Field/2} / / / / Based on the description, how likely would you be to purchase... (7) | S2: How different is this product from other products on the market today? (1) | T2: How different is this product from other products on the market today? (2) | U2: How different is this product from other products on the market today? (3) | V2: How different is this product from other products on the market today? (4) | W2: How different is this product from other products on the market today? (5) | X2: How different is this product from other products on the market today? (6) | Y2: How different is this product from other products on the market today? (7) | Z2: If you tried this product and it met your expectations for taste and effectiveness, how often could... (1) | AA2: If you tried this product and it met your expectations for taste and effectiveness, how often could... (2) | AB2: If you tried this product and it met your expectations for taste and effectiveness, how often could... (3) | AC2: If you tried this product and it met your expectations for taste and effectiveness, how often could... (4) | AD2: If you tried this product and it met your expectations for taste and effectiveness, how often could... (5) | AE2: If you tried this product and it met your expectations for taste and effectiveness, how often could... (6) | AF2: If you tried this product and it met your expectations for taste and effectiveness, how often could... (7) | AG2: If you tried this product and it met your expectations for taste and effectiveness, which of the fol... (1)-Regular coffee or espresso, latte, cappuccino, etc (not decaffeinated) | AH2: If you tried this product and it met your expectations for taste and effectiveness, which of the fol... (1)-Caffeinated soda (examples: Coke, Pepsi, Mountain Dew) | AI2: If you tried this product and it met your expectations for taste and effectiveness, which of the fol... (1)-Any brand of caffeinated energy drink (examples: Monster, Rockstar, Red Bull) | AJ2: If you tried this product and it met your expectations for taste and effectiveness, which of the fol... (1)-Any brand of energy shots (example: 5-hr energy) | AK2: If you tried this product and it met your expectations for taste and effectiveness, which of the fol... (1)-Any brand of energy bars (example: PowerBar, LunaBar, Clif Bar) | AL2: If you tried this product and it met your expectations for taste and effectiveness, which of the fol... (2)-Regular coffee or espresso, latte, cappuccino, etc (not decaffeinated) | AM2: If you tried this product and it met your expectations for taste and effectiveness, which of the fol... (2)-Caffeinated soda (examples: Coke, Pepsi, Mountain Dew) | AN2: If you tried this product and it met your expectations for taste and effectiveness, which of the fol... (2)-Any brand of caffeinated energy drink (examples: Monster, Rockstar, Red Bull) | AO2: If you tried this product and it met your expectations for taste and effectiveness, which of the fol... (2)-Any brand of energy shots (example: 5-hr energy) | AP2: If you tried this product and it met your expectations for taste and effectiveness, which of the fol... (2)-Any brand of energy bars (example: PowerBar, LunaBar, Clif Bar) | AQ2: If you tried this product and it met your expectations for taste and effectiveness, which of the fol... (3)-Regular coffee or espresso, latte, cappuccino, etc (not decaffeinated) | AR2: If you tried this product and it met your expectations for taste and effectiveness, which of the fol... (3)-Caffeinated soda (examples: Coke, Pepsi, Mountain Dew) | AS2: If you tried this product and it met your expectations for taste and effectiveness, which of the fol... (3)-Any brand of caffeinated energy drink (examples: Monster, Rockstar, Red Bull) | AT2: If you tried this product and it met your expectations for taste and effectiveness, which of the fol... (3)-Any brand of energy shots (example: 5-hr energy) | AU2: If you tried this product and it met your expectations for taste and effectiveness, which of the fol... (3)-Any brand of energy bars (example: PowerBar, LunaBar, Clif Bar) | AV2: If you tried this product and it met your expectations for taste and effectiveness, which of the fol... (4)-Regular coffee or espresso, latte, cappuccino, etc (not decaffeinated) | AW2: If you tried this product and it met your expectations for taste and effectiveness, which of the fol... (4)-Caffeinated soda (examples: Coke, Pepsi, Mountain Dew) | AX2: If you tried this product and it met your expectations for taste and effectiveness, which of the fol... (4)-Any brand of caffeinated energy drink (examples: Monster, Rockstar, Red Bull) | AY2: If you tried this product and it met your expectations for taste and effectiveness, which of the fol... (4)-Any brand of energy shots (example: 5-hr energy) | AZ2: If you tried this product and it met your expectations for taste and effectiveness, which of the fol... (4)-Any brand of energy bars (example: PowerBar, LunaBar, Clif Bar) | BA2: If you tried this product and it met your expectations for taste and effectiveness, which of the fol... (5)-Regular coffee or espresso, latte, cappuccino, etc (not decaffeinated) | BB2: If you tried this product and it met your expectations for taste and effectiveness, which of the fol... (5)-Caffeinated soda (examples: Coke, Pepsi, Mountain Dew) | BC2: If you tried this product and it met your expectations for taste and effectiveness, which of the fol... (5)-Any brand of caffeinated energy drink (examples: Monster, Rockstar, Red Bull) | BD2: If you tried this product and it met your expectations for taste and effectiveness, which of the fol... (5)-Any brand of energy shots (example: 5-hr energy) | BE2: If you tried this product and it met your expectations for taste and effectiveness, which of the fol... (5)-Any brand of energy bars (example: PowerBar, LunaBar, Clif Bar) | BF2: If you tried this product and it met your expectations for taste and effectiveness, which of the fol... (6)-Regular coffee or espresso, latte, cappuccino, etc (not decaffeinated) | BG2: If you tried this product and it met your expectations for taste and effectiveness, which of the fol... (6)-Caffeinated soda (examples: Coke, Pepsi, Mountain Dew) | BH2: If you tried this product and it met your expectations for taste and effectiveness, which of the fol... (6)-Any brand of caffeinated energy drink (examples: Monster, Rockstar, Red Bull) | BI2: If you tried this product and it met your expectations for taste and effectiveness, which of the fol... (6)-Any brand of energy shots (example: 5-hr energy) | BJ2: If you tried this product and it met your expectations for taste and effectiveness, which of the fol... (6)-Any brand of energy bars (example: PowerBar, LunaBar, Clif Bar) | BK2: If you tried this product and it met your expectations for taste and effectiveness, which of the fol... (7)-Regular coffee or espresso, latte, cappuccino, etc (not decaffeinated) | BL2: If you tried this product and it met your expectations for taste and effectiveness, which of the fol... (7)-Caffeinated soda (examples: Coke, Pepsi, Mountain Dew) | BM2: If you tried this product and it met your expectations for taste and effectiveness, which of the fol... (7)-Any brand of caffeinated energy drink (examples: Monster, Rockstar, Red Bull) | BN2: If you tried this product and it met your expectations for taste and effectiveness, which of the fol... (7)-Any brand of energy shots (example: 5-hr energy) | BO2: If you tried this product and it met your expectations for taste and effectiveness, which of the fol... (7)-Any brand of energy bars (example: PowerBar, LunaBar, Clif Bar)
A3: R_1N3XDZzeYAGCpUg | B3: 1 | C3: 2 | D3: 3 | E3: 1 | F3: 3 | G3: 2 | H3: 1 | I3: 1 | J3: 2 | K3: 1 | L3: 3 | M3: 4 | N3: 3 | O3: 2 | P3: 3 | Q3: 2 | R3: 2 | S3: 1 | T3: 1 | U3: 1 | V3: 1 | W3: 1 | X3: 1 | Y3: 1 | Z3: 2 | AA3: 2 | AB3: 1 | AC3: 1 | AD3: 1 | AE3: 1 | AF3: 2 | AG3: 1 | AH3: 0 | AI3: 0 | AJ3: 0 | AK3: 0 | AL3: 1 | AM3: 0 | AN3: 0 | AO3: 0 | AP3: 0 | AQ3: 1 | AR3: 0 | AS3: 0 | AT3: 0 | AU3: 0 | AV3: 1 | AW3: 0 | AX3: 0 | AY3: 0 | AZ3: 0 | BA3: 1 | BB3: 0 | BC3: 0 | BD3: 0 | BE3: 0 | BF3: 1 | BG3: 0 | BH3: 0 | BI3: 0 | BJ3: 0 | BK3: 1 | BL3: 0 | BM3: 0 | BN3: 0 | BO3: 0
A4: R_2hEs3JHZUXaaSYA | B4: 1 | C4: 1 | D4: 4 | E4: 3 | F4: 5 | G4: 2 | H4: 1 | I4: 1 | J4: 4 | K4: 1 | L4: 3 | M4: 3 | N4: 3 | O4: 1 | P4: 2 | Q4: 2 | R4: 1 | S4: 2 | T4: 1 | U4: 5 | V4: 1 | W4: 2 | X4: 1 | Y4: 1 | Z4: 2 | AA4: 1 | AB4: 2 | AC4: 1 | AD4: 1 | AE4: 1 | AF4: 1 | AG4: 1 | AH4: 0 | AI4: 0 | AJ4: 0 | AK4: 1 | AL4: 1 | AM4: 0 | AN4: 0 | AO4: 0 | AP4: 0 | AQ4: 1 | AR4: 0 | AS4: 0 | AT4: 0 | AU4: 0 | AV4: 0 | AW4: 0 | AX4: 0 | AY4: 0 | AZ4: 0 | BA4: 1 | BB4: 0 | BC4: 0 | BD4: 0 | BE4: 0 | BF4: 1 | BG4: 0 | BH4: 0 | BI4: 0 | BJ4: 0 | BK4: 0 | BL4: 0 | BM4: 0 | BN4: 0 | BO4: 0
A5: R_38Jse9gTmty1CAI | B5: 1 | C5: 2 | D5: 2 | E5: 3 | F5: 1 | G5: 4 | H5: 1 | I5: 1 | J5: 2 | K5: 1 | L5: 4 | M5: 3 | N5: 4 | O5: 2 | P5: 3 | Q5: 4 | R5: 1 | S5: 1 | T5: 1 | U5: 1 | V5: 1 | W5: 1 | X5: 1 | Y5: 1 | Z5: 3 | AA5: 2 | AB5: 3 | AC5: 5 | AD5: 2 | AE5: 2 | AF5: 5 | AG5: 0 | AH5: 1 | AI5: 0 | AJ5: 0 | AK5: 0 | AL5: 0 | AM5: 1 | AN5: 0 | AO5: 0 | AP5: 0 | AQ5: 0 | AR5: 1 | AS5: 0 | AT5: 0 | AU5: 0 | AV5: 0 | AW5: 0 | AX5: 0 | AY5: 0 | AZ5: 0 | BA5: 0 | BB5: 1 | BC5: 0 | BD5: 0 | BE5: 0 | BF5: 0 | BG5: 0 | BH5: 0 | BI5: 0 | BJ5: 0 | BK5: 0 | BL5: 0 | BM5: 0 | BN5: 0 | BO5: 0
A6: R_cYg4TVl3b3ixPOk | B6: 1 | C6: 1 | D6: 4 | E6: 3 | F6: 5 | G6: 5 | H6: 2 | I6: 1 | J6: 3 | K6: 1 | L6: 3 | M6: 2 | N6: 2 | O6: 2 | P6: 3 | Q6: 3 | R6: 1 | S6: 1 | T6: 1 | U6: 1 | V6: 1 | W6: 2 | X6: 1 | Y6: 1 | Z6: 1 | AA6: 5 | AB6: 5 | AC6: 5 | AD6: 2 | AE6: 2 | AF6: 5 | AG6: 0 | AH6: 0 | AI6: 0 | AJ6: 0 | AK6: 1 | AL6: 0 | AM6: 0 | AN6: 0 | AO6: 0 | AP6: 0 | AQ6: 0 | AR6: 0 | AS6: 0 | AT6: 0 | AU6: 1 | AV6: 0 | AW6: 0 | AX6: 0 | AY6: 0 | AZ6: 0 | BA6: 1 | BB6: 0 | BC6: 0 | BD6: 0 | BE6: 0 | BF6: 1 | BG6: 0 | BH6: 0 | BI6: 0 | BJ6: 0 | BK6: 0 | BL6: 0 | BM6: 0 | BN6: 0 | BO6: 0
A7: R_5c0BDuZ4Tk7wbWc | B7: 1 | C7: 2 | D7: 4 | E7: 2 | F7: 5 | G7: 3 | H7: 1 | I7: 1 | J7: 2 | K7: 1 | L7: 2 | M7: 2 | N7: 2 | O7: 2 | P7: 2 | Q7: 1 | R7: 1 | S7: 1 | T7: 5 | U7: 2 | V7: 1 | W7: 5 | X7: 1 | Y7: 1 | Z7: 2 | AA7: 5 | AB7: 1 | AC7: 5 | AD7: 5 | AE7: 5 | AF7: 5 | AG7: 0 | AH7: 0 | AI7: 0 | AJ7: 1 | AK7: 1 | AL7: 0 | AM7: 0 | AN7: 0 | AO7: 0 | AP7: 0 | AQ7: 0 | AR7: 0 | AS7: 0 | AT7: 0 | AU7: 0 | AV7: 0 | AW7: 0 | AX7: 0 | AY7: 0 | AZ7: 0 | BA7: 0 | BB7: 0 | BC7: 0 | BD7: 0 | BE7: 0 | BF7: 0 | BG7: 0 | BH7: 0 | BI7: 0 | BJ7: 0 | BK7: 0 | BL7: 0 | BM7: 0 | BN7: 0 | BO7: 0
A8: R_9QV62ZpbKRi2PE8 | B8: 1 | C8: 2 | D8: 5 | E8: 4 | F8: 4 | G8: 3 | H8: 1 | I8: 1 | J8: 4 | K8: 1 | L8: 3 | M8: 1 | N8: 3 | O8: 1 | P8: 1 | Q8: 4 | R8: 1 | S8: 1 | T8: 5 | U8: 1 | V8: 1 | W8: 2 | X8: 1 | Y8: 1 | Z8: 5 | AA8: 5 | AB8: 5 | AC8: 5 | AD8: 5 | AE8: 3 | AF8: 5 | AG8: 0 | AH8: 0 | AI8: 0 | AJ8: 0 | AK8: 1 | AL8: 0 | AM8: 0 | AN8: 0 | AO8: 0 | AP8: 0 | AQ8: 1 | AR8: 1 | AS8: 1 | AT8: 1 | AU8: 0 | AV8: 0 | AW8: 0 | AX8: 0 | AY8: 0 | AZ8: 0 | BA8: 0 | BB8: 0 | BC8: 1 | BD8: 1 | BE8: 0 | BF8: 0 | BG8: 0 | BH8: 1 | BI8: 1 | BJ8: 0 | BK8: 0 | BL8: 0 | BM8: 0 | BN8: 0 | BO8: 0
A9: R_6VF0PKQjBZfKr7S | B9: 1 | C9: 1 | D9: 5 | E9: 3 | F9: 5 | G9: 4 | H9: 2 | I9: 1 | J9: 3 | K9: 1 | L9: 2 | M9: 2 | N9: 2 | O9: 2 | P9: 2 | Q9: 2 | R9: 2 | S9: 5 | T9: 5 | U9: 5 | V9: 5 | W9: 5 | X9: 5 | Y9: 5 | Z9: 5 | AA9: 5 | AB9: 5 | AC9: 5 | AD9: 5 | AE9: 5 | AF9: 5 | AG9: 0 | AH9: 0 | AI9: 0 | AJ9: 0 | AK9: 0 | AL9: 0 | AM9: 0 | AN9: 0 | AO9: 0 | AP9: 0 | AQ9: 0 | AR9: 0 | AS9: 0 | AT9: 0 | AU9: 0 | AV9: 0 | AW9: 0 | AX9: 0 | AY9: 0 | AZ9: 0 | BA9: 0 | BB9: 0 | BC9: 0 | BD9: 0 | BE9: 0 | BF9: 0 | BG9: 0 | BH9: 0 | BI9: 0 | BJ9: 0 | BK9: 0 | BL9: 0 | BM9: 0 | BN9: 0 | BO9: 0
A10: R_0P8INO0Tzq2zeQs | B10: 1 | C10: 1 | D10: 4 | E10: 3 | F10: 5 | G10: 3 | H10: 2 | I10: 1 | J10: 3 | K10: 1 | L10: 3 | M10: 1 | N10: 3 | O10: 1 | P10: 2 | Q10: 1 | R10: 1 | S10: 1 | T10: 1 | U10: 1 | V10: 1 | W10: 2 | X10: 1 | Y10: 1 | Z10: 1 | AA10: 1 | AB10: 1 | AC10: 1 | AD10: 1 | AE10: 1 | AF10: 1 | AG10: 1 | AH10: 0 | AI10: 0 | AJ10: 0 | AK10: 0 | AL10: 0 | AM10: 1 | AN10: 0 | AO10: 0 | AP10: 0 | AQ10: 1 | AR10: 1 | AS10: 0 | AT10: 0 | AU10: 0 | AV10: 0 | AW10: 0 | AX10: 0 | AY10: 0 | AZ10: 0 | BA10: 0 | BB10: 1 | BC10: 1 | BD10: 0 | BE10: 0 | BF10: 0 | BG10: 0 | BH10: 0 | BI10: 0 | BJ10: 0 | BK10: 0 | BL10: 0 | BM10: 0 | BN10: 0 | BO10: 0
A11: R_81zLXDJMGXq9oFK | B11: 1 | C11: 2 | D11: 4 | E11: 4 | F11: 5 | G11: 3 | H11: 1 | I11: 1 | J11: 2 | K11: 1 | L11: 4 | M11: 3 | N11: 4 | O11: 1 | P11: 4 | Q11: 1 | R11: 1 | S11: 2 | T11: 2 | U11: 2 | V11: 1 | W11: 2 | X11: 1 | Y11: 1 | Z11: 1 | AA11: 1 | AB11: 2 | AC11: 0 | AD11: 2 | AE11: 5 | AF11: 5 | AG11: 1 | AH11: 1 | AI11: 0 | AJ11: 0 | AK11: 0 | AL11: 0 | AM11: 0 | AN11: 0 | AO11: 0 | AP11: 0 | AQ11: 1 | AR11: 1 | AS11: 0 | AT11: 0 | AU11: 0 | AV11: 0 | AW11: 0 | AX11: 0 | AY11: 0 | AZ11: 0 | BA11: 0 | BB11: 1 | BC11: 0 | BD11: 0 | BE11: 0 | BF11: 0 | BG11: 0 | BH11: 0 | BI11: 0 | BJ11: 0 | BK11: 0 | BL11: 0 | BM11: 0 | BN11: 0 | BO11: 0
A12: R_3sLH9DHixuCE4u0 | B12: 1 | C12: 2 | D12: 4 | E12: 3 | F12: 5 | G12: 5 | H12: 1 | I12: 1 | J12: 2 | K12: 1 | L12: 5 | M12: 4 | N12: 5 | O12: 3 | P12: 2 | Q12: 5 | R12: 1 | S12: 1 | T12: 2 | U12: 1 | V12: 1 | W12: 2 | X12: 1 | Y12: 1 | Z12: 3 | AA12: 1 | AB12: 3 | AC12: 2 | AD12: 2 | AE12: 3 | AF12: 5 | AG12: 0 | AH12: 0 | AI12: 1 | AJ12: 1 | AK12: 1 | AL12: 0 | AM12: 1 | AN12: 1 | AO12: 1 | AP12: 1 | AQ12: 0 | AR12: 0 | AS12: 1 | AT12: 1 | AU12: 1 | AV12: 0 | AW12: 0 | AX12: 1 | AY12: 1 | AZ12: 1 | BA12: 0 | BB12: 0 | BC12: 1 | BD12: 1 | BE12: 1 | BF12: 1 | BG12: 0 | BH12: 1 | BI12: 1 | BJ12: 1 | BK12: 0 | BL12: 0 | BM12: 1 | BN12: 1 | BO12: 1
A13: R_8c8aknIt7HdgXbK | B13: 1 | C13: 2 | D13: 5 | E13: 0 | F13: 5 | G13: 3 | H13: 1 | I13: 1 | J13: 4 | K13: 1 | L13: 3 | M13: 3 | N13: 4 | O13: 3 | P13: 5 | Q13: 3 | R13: 1 | S13: 5 | T13: 5 | U13: 5 | V13: 5 | W13: 1 | X13: 5 | Y13: 5 | Z13: 2 | AA13: 5 | AB13: 3 | AC13: 5 | AD13: 3 | AE13: 5 | AF13: 5 | AG13: 0 | AH13: 1 | AI13: 1 | AJ13: 0 | AK13: 0 | AL13: 0 | AM13: 1 | AN13: 0 | AO13: 0 | AP13: 0 | AQ13: 0 | AR13: 1 | AS13: 0 | AT13: 0 | AU13: 0 | AV13: 0 | AW13: 1 | AX13: 0 | AY13: 0 | AZ13: 0 | BA13: 1 | BB13: 1 | BC13: 0 | BD13: 0 | BE13: 0 | BF13: 0 | BG13: 1 | BH13: 0 | BI13: 0 | BJ13: 0 | BK13: 0 | BL13: 1 | BM13: 0 | BN13: 0 | BO13: 0
A14: R_e41NPQokSj4fakc | B14: 1 | C14: 2 | D14: 4 | E14: 2 | F14: 4 | G14: 4 | H14: 1 | I14: 1 | J14: 2 | K14: 1 | L14: 2 | M14: 1 | N14: 2 | O14: 3 | P14: 4 | Q14: 2 | R14: 1 | S14: 2 | T14: 2 | U14: 3 | V14: 1 | W14: 1 | X14: 1 | Y14: 1 | Z14: 1 | AA14: 1 | AB14: 1 | AC14: 2 | AD14: 3 | AE14: 2 | AF14: 1 | AG14: 0 | AH14: 0 | AI14: 0 | AJ14: 0 | AK14: 0 | AL14: 0 | AM14: 0 | AN14: 0 | AO14: 0 | AP14: 0 | AQ14: 0 | AR14: 0 | AS14: 0 | AT14: 0 | AU14: 0 | AV14: 0 | AW14: 1 | AX14: 0 | AY14: 0 | AZ14: 0 | BA14: 1 | BB14: 1 | BC14: 0 | BD14: 0 | BE14: 0 | BF14: 1 | BG14: 1 | BH14: 0 | BI14: 0 | BJ14: 0 | BK14: 0 | BL14: 0 | BM14: 0 | BN14: 0 | BO14: 0
... A152: R_7VSQFKreAYzM8HW | B152: 0 | C152: 1 | D152: 3 | E152: 3 | F152: 2 | G152: 2 | H152: 1 | I152: 1 | J152: 2 | K152: 1 | L152: 0 | M152: 2 | N152: 0 | O152: 0 | P152: 0 | Q152: 0 | R152: 0 | S152: 0 | T152: 1 | U152: 0 | V152: 0 | W152: 0 | X152: 0 | Y152: 0 | Z152: 0 | AA152: 5 | AB152: 0 | AC152: 0 | AD152: 0 | AE152: 0 | AF152: 0 | AG152: 0 | AH152: 0 | AI152: 0 | AJ152: 0 | AK152: 0 | AL152: 0 | AM152: 0 | AN152: 0 | AO152: 0 | AP152: 0 | AQ152: 0 | AR152: 0 | AS152: 0 | AT152: 0 | AU152: 0 | AV152: 0 | AW152: 0 | AX152: 0 | AY152: 0 | AZ152: 0 | BA152: 0 | BB152: 0 | BC152: 0 | BD152: 0 | BE152: 0 | BF152: 0 | BG152: 0 | BH152: 0 | BI152: 0 | BJ152: 0 | BK152: 0 | BL152: 0 | BM152: 0 | BN152: 0 | BO152: 0

Sheet DataT
A1: {=TRANSPOSE(Data!A1:BO152)} -> V1 | B1: ResponseID | C1: R_1N3XDZzeYAGCpUg | D1: R_2hEs3JHZUXaaSYA | E1: R_38Jse9gTmty1CAI | F1: R_cYg4TVl3b3ixPOk | G1: R_5c0BDuZ4Tk7wbWc | H1: R_9QV62ZpbKRi2PE8 | I1: R_6VF0PKQjBZfKr7S | J1: R_0P8INO0Tzq2zeQs | K1: R_81zLXDJMGXq9oFK | L1: R_3sLH9DHixuCE4u0 | M1: R_8c8aknIt7HdgXbK | N1: R_e41NPQokSj4fakc | O1: R_b1xUJGNyS7QH1Xu | P1: R_2cvm1lfqDiLoOPy | Q1: R_8DgeiQSH8BnWYPG | R1: R_24v5y5vg3k101rm | S1: R_3atYTE9YIuhdrUg | T1: R_0Ta2p5cLJGvqnNq | U1: R_5bvAqWlkXN1AhJW | V1: R_2bntE3vTTPKdH3S | W1: R_0Sxutiqb3QjcyZm | X1: R_8H24QRDoYeaDMTW | Y1: R_8B7cJVT6LZHXbMM | Z1: R_blwhb0d7OLziQPa | AA1: R_5zI5C2Bd9JFIKVu | AB1: R_b9hO3njrSa4FNuQ | AC1: R_2tLzeYAyQ5chInq | AD1: R_7agsNu1aZdY1cyM | AE1: R_0fuAvuUUCSanXus | AF1: R_8HszmdgxRevFzYU | AG1: R_1Y3A7WrCN0C3x7S | AH1: R_5BgcvkVoFdlOvNW | AI1: R_8udbWXzDet0GKOg | AJ1: R_9pgVAOIS5RNdhic | AK1: R_d3XRGmoTiF255Jy | AL1: R_czLoMb4AAKU97GQ | AM1: R_3gehWHoeFWMPLs8 | AN1: R_b2b1OI4mD4UlEhu | AO1: R_6VUIhHJpkrRC9Du | AP1: R_6MyPP6U8zBE80HG | AQ1: R_6RwhJiwW0fKQa1K | AR1: R_8BpNCF6KBdP3m7O | AS1: R_3sbA6J5E4f8yRU0 | AT1: R_bf79r4tXx4ndude | AU1: R_1X1TsPn0lTbVmCw | AV1: R_3VikZb29icPCvRy | AW1: R_e5LkomApIs4Sitm | AX1: R_eaH8EuQxXHrtrso | AY1: R_cHfq2fHbMo6F0qg | AZ1: R_eIBW9Yii3HTXyeg | BA1: R_bdcCo2wzvtmI8G8 | BB1: R_74mDVT83kC4s5UM | BC1: R_cMkCzG4DamjfAqw | BD1: R_bHj2OIkRe19SQ9S | BE1: R_82NFNR0WWrE0Lzu | BF1: R_esxLUjofDycprzm | BG1: R_1zEbqCS23INKnvS | BH1: R_cLRrEjkbHH11iUQ | BI1: R_6wXzlxTfNSeumUs | BJ1: R_80L6qhXQLvfFm4s | BK1: R_3RdepmZ1SgZPiuM | BL1: R_aWexD1nQGXTdKp6 | BM1: R_06VgxzvQraMdZJ2 | BN1: R_9FFltFTXURLadWQ | BO1: R_5t1UvoWhZ3rap7u | BP1: R_ezAKae3yPze4afa | BQ1: R_b9kKAmvhhpyP3bm | BR1: R_cIIlNTaBL37VVas | BS1: R_e4AXBJ3ggQ1H7Ug | BT1: R_enEvnNTbfaxLFUE | BU1: R_864phvpmcd9bi0k | BV1: R_4PCy0WvFyjBMBNi | BW1: R_b10feHU6ZvTf3U0 | BX1: R_3POvwJStfLEFLM0 | BY1: R_8qAeuyTFks9UrQw | BZ1: R_5irZgmwUdqYvx6Q | CA1: R_a027OiD81LmMu56 | CB1: R_5pCZUHY1zaSfIuo | CC1: R_00O8YuoLCNshxCA | CD1: R_dfZf0Goz3qOxjr6 | CE1: R_6J2J9DWFgn1qBuY | CF1: R_8B57zcoKnlEbji4 | CG1: R_0x3BvWddMfjdcyw | CH1: R_2hkw3NSScgVFB8E | CI1: R_bI27yFNU2C7vXwg | CJ1: R_6DJswFlddUY8nKQ | CK1: R_6L3eGi1u7io5508 | CL1: R_8HX9qQh2OBxDG2o | CM1: R_a5xxjAz6XSKNbec | CN1: R_1Zgz9bvERjY42e8 | CO1: R_eVPstF5xi7m5AoY | CP1: R_2nx0Fbe6Ugd3e04 | CQ1: R_2tU2uy4XHQXkAra | CR1: R_czROXkZA5goPSsI | CS1: R_eevGdaukcGRcx36 | CT1: R_bawdK5I4Cs5sQIc | CU1: R_3qOi0AfW6wCZjQo | CV1: R_d70ASQYaSttavJO | CW1: R_0jPzFwj4JrKKdCY | CX1: R_d4NoisYdAoF2ZBa | CY1: R_77X2VAqww4Tp1s0 | CZ1: R_bNHqRWLdOkEwc3a | DA1: R_0epDpaTVxgFwAFC | DB1: R_6XVBRIvEaZx84Sw | DC1: R_3W9XEbBEWQjWjKA | DD1: R_291oJLRttSa66uE | DE1: R_9WuxFw6R4KKNE56 | DF1: R_0qCjfd73gqmseFe | DG1: R_cUYsP7IxAST4HxW | DH1: R_1NA8Sl16UkNjFqc | DI1: R_ebOUtv1eT91Vq2E | DJ1: R_a986RCZ8OoAtOug | DK1: R_9treiOri67f72HG | DL1: R_7QYlHE57IkUzaCM | DM1: R_3UZkukTCwax3znu | DN1: R_5zJylbBuLqE6aFe | DO1: R_ePVTJyPrMhG698g | DP1: R_aV7KpWXgDms8au8 | DQ1: R_6FsGl1z2gF2B3ta | DR1: R_bdsv5Zn4Ulk8hGA | DS1: R_9FhttXpZmn5OtDK | DT1: R_8ifDrAk9rUU5wIQ | DU1: R_5pW1I9P2Qmu71Bi | DV1: R_bBDAihFpwSzZP0w | DW1: R_bvElC0HiBE6hkeE | DX1: R_5aPjJhwQEjKbqL2 | DY1: R_bJVI898wPa1eR8g | DZ1: R_3PHfhGyp7KdjegA | EA1: R_2laPrFYGvYVtGuw | EB1: R_9yOCAZMKKmJFGVS | EC1: R_1GhiLP3NoBXsXXe | ED1: R_0d2n33Qs2deKxBG | EE1: R_e9u6cYN1Zy7YTBi | EF1: R_9pNFIbalbkjH35q | EG1: R_6L38v6AyBOP2uuo | EH1: R_cSmbUKOUcqKTjMw | EI1: R_cYM8umBzQs6rXDe | EJ1: R_0roEQqF3dEUD3bS | EK1: R_6ExAmbnXeLA4Kck | EL1: R_7UkPyCGhS3M0zEo | EM1: R_6VbgOBkZCrh8oFS | EN1: R_554amT6gLrJn31O | EO1: R_bNHCcEhS1DLYeOM | EP1: R_4TaaClNGEQOwYi8 | EQ1: R_6mcDwONpiGXq7tO | ER1: R_40HI99JZAFdNVXu | ES1: R_0e0sxaucmV8dH7u | ET1: R_38cJSy405X3R9qs | EU1: R_8bRFlkMzBEsuiBC | EV1: R_7VSQFKreAYzM8HW
A2: V10 | B2: Finished | C2: 1 | D2: 1 | E2: 1 | F2: 1 | G2: 1 | H2: 1 | I2: 1 | J2: 1 | K2: 1 | L2: 1 | M2: 1 | N2: 1 | O2: 1 | P2: 1 | Q2: 1 | R2: 1 | S2: 1 | T2: 1 | U2: 1 | V2: 1 | W2: 1 | X2: 1 | Y2: 1 | Z2: 1 | AA2: 1 | AB2: 1 | AC2: 1 | AD2: 1 | AE2: 1 | AF2: 1 | AG2: 1 | AH2: 1 | AI2: 1 | AJ2: 1 | AK2: 1 | AL2: 1 | AM2: 1 | AN2: 1 | AO2: 1 | AP2: 1 | AQ2: 1 | AR2: 1 | AS2: 1 | AT2: 1 | AU2: 1 | AV2: 1 | AW2: 1 | AX2: 1 | AY2: 1 | AZ2: 1 | BA2: 1 | BB2: 1 | BC2: 1 | BD2: 1 | BE2: 1 | BF2: 1 | BG2: 1 | BH2: 1 | BI2: 1 | BJ2: 1 | BK2: 1 | BL2: 1 | BM2: 1 | BN2: 1 | BO2: 1 | BP2: 1 | BQ2: 1 | BR2: 1 | BS2: 1 | BT2: 1 | BU2: 1 | BV2: 1 | BW2: 1 | BX2: 1 | BY2: 1 | BZ2: 1 | CA2: 1 | CB2: 1 | CC2: 1 | CD2: 1 | CE2: 1 | CF2: 1 | CG2: 1 | CH2: 1 | CI2: 1 | CJ2: 1 | CK2: 1 | CL2: 1 | CM2: 1 | CN2: 1 | CO2: 1 | CP2: 1 | CQ2: 1 | CR2: 1 | CS2: 1 | CT2: 1 | CU2: 1 | CV2: 1 | CW2: 1 | CX2: 1 | CY2: 1 | CZ2: 1 | DA2: 1 | DB2: 1 | DC2: 1 | DD2: 1 | DE2: 1 | DF2: 1 | DG2: 1 | DH2: 1 | DI2: 1 | DJ2: 1 | DK2: 1 | DL2: 1 | DM2: 1 | DN2: 1 | DO2: 1 | DP2: 1 | DQ2: 1 | DR2: 1 | DS2: 1 | DT2: 1 | DU2: 1 | DV2: 1 | DW2: 1 | DX2: 1 | DY2: 1 | DZ2: 1 | EA2: 1 | EB2: 1 | EC2: 1 | ED2: 1 | EE2: 1 | EF2: 0 | EG2: 0 | EH2: 0 | EI2: 1 | EJ2: 0 | EK2: 1 | EL2: 1 | EM2: 0 | EN2: 0 | EO2: 0 | EP2: 0 | EQ2: 1 | ER2: 0 | ES2: 1 | ET2: 1 | EU2: 0 | EV2: 0
A3: GEN | B3: Background questions / / Your gender? | C3: 2 | D3: 1 | E3: 2 | F3: 1 | G3: 2 | H3: 2 | I3: 1 | J3: 1 | K3: 2 | L3: 2 | M3: 2 | N3: 2 | O3: 1 | P3: 2 | Q3: 2 | R3: 0 | S3: 1 | T3: 1 | U3: 1 | V3: 2 | W3: 2 | X3: 2 | Y3: 1 | Z3: 2 | AA3: 2 | AB3: 1 | AC3: 1 | AD3: 1 | AE3: 2 | AF3: 1 | AG3: 1 | AH3: 2 | AI3: 2 | AJ3: 2 | AK3: 2 | AL3: 1 | AM3: 2 | AN3: 2 | AO3: 2 | AP3: 2 | AQ3: 2 | AR3: 1 | AS3: 2 | AT3: 2 | AU3: 2 | AV3: 2 | AW3: 2 | AX3: 2 | AY3: 2 | AZ3: 2 | BA3: 1 | BB3: 2 | BC3: 1 | BD3: 2 | BE3: 2 | BF3: 2 | BG3: 2 | BH3: 2 | BI3: 2 | BJ3: 1 | BK3: 2 | BL3: 2 | BM3: 2 | BN3: 2 | BO3: 1 | BP3: 2 | BQ3: 2 | BR3: 2 | BS3: 2 | BT3: 1 | BU3: 2 | BV3: 2 | BW3: 2 | BX3: 2 | BY3: 1 | BZ3: 2 | CA3: 2 | CB3: 2 | CC3: 2 | CD3: 2 | CE3: 2 | CF3: 1 | CG3: 2 | CH3: 2 | CI3: 1 | CJ3: 2 | CK3: 2 | CL3: 2 | CM3: 2 | CN3: 2 | CO3: 2 | CP3: 2 | CQ3: 2 | CR3: 2 | CS3: 1 | CT3: 2 | CU3: 2 | CV3: 2 | CW3: 2 | CX3: 1 | CY3: 2 | CZ3: 2 | DA3: 1 | DB3: 2 | DC3: 1 | DD3: 1 | DE3: 1 | DF3: 2 | DG3: 2 | DH3: 2 | DI3: 2 | DJ3: 2 | DK3: 2 | DL3: 2 | DM3: 2 | DN3: 1 | DO3: 2 | DP3: 2 | DQ3: 2 | DR3: 1 | DS3: 2 | DT3: 1 | DU3: 2 | DV3: 2 | DW3: 1 | DX3: 1 | DY3: 2 | DZ3: 2 | EA3: 2 | EB3: 2 | EC3: 1 | ED3: 1 | EE3: 2 | EF3: 0 | EG3: 0 | EH3: 0 | EI3: 2 | EJ3: 1 | EK3: 2 | EL3: 2 | EM3: 0 | EN3: 1 | EO3: 0 | EP3: 0 | EQ3: 2 | ER3: 0 | ES3: 1 | ET3: 1 | EU3: 2 | EV3: 1
A4: AGE | B4: Your age? | C4: 3 | D4: 4 | E4: 2 | F4: 4 | G4: 4 | H4: 5 | I4: 5 | J4: 4 | K4: 4 | L4: 4 | M4: 5 | N4: 4 | O4: 4 | P4: 2 | Q4: 3 | R4: 4 | S4: 4 | T4: 4 | U4: 5 | V4: 3 | W4: 2 | X4: 3 | Y4: 3 | Z4: 3 | AA4: 3 | AB4: 3 | AC4: 3 | AD4: 3 | AE4: 3 | AF4: 3 | AG4: 3 | AH4: 3 | AI4: 3 | AJ4: 3 | AK4: 3 | AL4: 3 | AM4: 4 | AN4: 4 | AO4: 4 | AP4: 2 | AQ4: 3 | AR4: 3 | AS4: 6 | AT4: 3 | AU4: 4 | AV4: 3 | AW4: 5 | AX4: 4 | AY4: 3 | AZ4: 3 | BA4: 3 | BB4: 3 | BC4: 3 | BD4: 4 | BE4: 4 | BF4: 4 | BG4: 3 | BH4: 4 | BI4: 4 | BJ4: 3 | BK4: 4 | BL4: 3 | BM4: 4 | BN4: 4 | BO4: 3 | BP4: 4 | BQ4: 4 | BR4: 3 | BS4: 5 | BT4: 3 | BU4: 5 | BV4: 5 | BW4: 4 | BX4: 5 | BY4: 4 | BZ4: 3 | CA4: 5 | CB4: 5 | CC4: 3 | CD4: 4 | CE4: 3 | CF4: 4 | CG4: 5 | CH4: 4 | CI4: 3 | CJ4: 3 | CK4: 3 | CL4: 4 | CM4: 3 | CN4: 5 | CO4: 4 | CP4: 5 | CQ4: 4 | CR4: 4 | CS4: 2 | CT4: 5 | CU4: 6 | CV4: 4 | CW4: 6 | CX4: 3 | CY4: 5 | CZ4: 5 | DA4: 5 | DB4: 3 | DC4: 3 | DD4: 5 | DE4: 5 | DF4: 5 | DG4: 3 | DH4: 4 | DI4: 5 | DJ4: 6 | DK4: 1 | DL4: 5 | DM4: 6 | DN4: 5 | DO4: 4 | DP4: 5 | DQ4: 5 | DR4: 4 | DS4: 3 | DT4: 3 | DU4: 6 | DV4: 5 | DW4: 6 | DX4: 5 | DY4: 5 | DZ4: 5 | EA4: 3 | EB4: 5 | EC4: 4 | ED4: 5 | EE4: 6 | EF4: 0 | EG4: 0 | EH4: 0 | EI4: 5 | EJ4: 3 | EK4: 2 | EL4: 4 | EM4: 0 | EN4: 4 | EO4: 0 | EP4: 0 | EQ4: 6 | ER4: 0 | ES4: 4 | ET4: 2 | EU4: 3 | EV4: 3
A5: EMP | B5: Employment status? | C5: 1 | D5: 3 | E5: 3 | F5: 3 | G5: 2 | H5: 4 | I5: 3 | J5: 3 | K5: 4 | L5: 3 | M5: 0 | N5: 2 | O5: 3 | P5: 1 | Q5: 3 | R5: 3 | S5: 1 | T5: 3 | U5: 3 | V5: 1 | W5: 1 | X5: 1 | Y5: 3 | Z5: 1 | AA5: 1 | AB5: 3 | AC5: 3 | AD5: 3 | AE5: 1 | AF5: 1 | AG5: 1 | AH5: 1 | AI5: 3 | AJ5: 3 | AK5: 1 | AL5: 3 | AM5: 3 | AN5: 3 | AO5: 3 | AP5: 1 | AQ5: 3 | AR5: 3 | AS5: 3 | AT5: 1 | AU5: 3 | AV5: 1 | AW5: 3 | AX5: 3 | AY5: 2 | AZ5: 1 | BA5: 3 | BB5: 3 | BC5: 3 | BD5: 2 | BE5: 2 | BF5: 3 | BG5: 3 | BH5: 3 | BI5: 4 | BJ5: 3 | BK5: 2 | BL5: 2 | BM5: 3 | BN5: 3 | BO5: 3 | BP5: 2 | BQ5: 2 | BR5: 3 | BS5: 4 | BT5: 3 | BU5: 4 | BV5: 2 | BW5: 2 | BX5: 3 | BY5: 3 | BZ5: 3 | CA5: 3 | CB5: 4 | CC5: 3 | CD5: 3 | CE5: 1 | CF5: 3 | CG5: 2 | CH5: 3 | CI5: 4 | CJ5: 3 | CK5: 3 | CL5: 4 | CM5: 3 | CN5: 4 | CO5: 3 | CP5: 2 | CQ5: 2 | CR5: 2 | CS5: 1 | CT5: 4 | CU5: 3 | CV5: 3 | CW5: 4 | CX5: 3 | CY5: 4 | CZ5: 3 | DA5: 3 | DB5: 3 | DC5: 3 | DD5: 3 | DE5: 3 | DF5: 3 | DG5: 2 | DH5: 3 | DI5: 2 | DJ5: 3 | DK5: 1 | DL5: 3 | DM5: 4 | DN5: 2 | DO5: 2 | DP5: 3 | DQ5: 2 | DR5: 3 | DS5: 1 | DT5: 1 | DU5: 4 | DV5: 3 | DW5: 3 | DX5: 3 | DY5: 3 | DZ5: 3 | EA5: 3 | EB5: 3 | EC5: 3 | ED5: 3 | EE5: 3 | EF5: 0 | EG5: 0 | EH5: 0 | EI5: 2 | EJ5: 1 | EK5: 3 | EL5: 2 | EM5: 0 | EN5: 3 | EO5: 0 | EP5: 0 | EQ5: 3 | ER5: 0 | ES5: 3 | ET5: 1 | EU5: 3 | EV5: 3
A6: CUR-USE_1 | B6: Rate your consumption for each of the following products:-Regular coffee or espresso, latte, cappuccino, etc (not decaffeinated) | C6: 3 | D6: 5 | E6: 1 | F6: 5 | G6: 5 | H6: 4 | I6: 5 | J6: 5 | K6: 5 | L6: 5 | M6: 5 | N6: 4 | O6: 5 | P6: 2 | Q6: 5 | R6: 4 | S6: 3 | T6: 5 | U6: 4 | V6: 2 | W6: 5 | X6: 5 | Y6: 3 | Z6: 5 | AA6: 3 | AB6: 5 | AC6: 5 | AD6: 2 | AE6: 5 | AF6: 5 | AG6: 5 | AH6: 1 | AI6: 5 | AJ6: 4 | AK6: 5 | AL6: 5 | AM6: 2 | AN6: 2 | AO6: 4 | AP6: 5 | AQ6: 5 | AR6: 5 | AS6: 5 | AT6: 5 | AU6: 2 | AV6: 4 | AW6: 5 | AX6: 5 | AY6: 5 | AZ6: 5 | BA6: 5 | BB6: 1 | BC6: 3 | BD6: 5 | BE6: 5 | BF6: 2 | BG6: 4 | BH6: 5 | BI6: 5 | BJ6: 3 | BK6: 2 | BL6: 4 | BM6: 5 | BN6: 5 | BO6: 5 | BP6: 1 | BQ6: 4 | BR6: 4 | BS6: 5 | BT6: 4 | BU6: 1 | BV6: 5 | BW6: 3 | BX6: 3 | BY6: 5 | BZ6: 5 | CA6: 5 | CB6: 2 | CC6: 5 | CD6: 3 | CE6: 1 | CF6: 5 | CG6: 4 | CH6: 5 | CI6: 3 | CJ6: 1 | CK6: 5 | CL6: 4 | CM6: 2 | CN6: 1 | CO6: 3 | CP6: 5 | CQ6: 5 | CR6: 5 | CS6: 2 | CT6: 5 | CU6: 5 | CV6: 5 | CW6: 2 | CX6: 5 | CY6: 5 | CZ6: 5 | DA6: 5 | DB6: 4 | DC6: 2 | DD6: 5 | DE6: 2 | DF6: 5 | DG6: 5 | DH6: 5 | DI6: 4 | DJ6: 5 | DK6: 3 | DL6: 5 | DM6: 5 | DN6: 5 | DO6: 5 | DP6: 5 | DQ6: 4 | DR6: 5 | DS6: 5 | DT6: 5 | DU6: 2 | DV6: 5 | DW6: 5 | DX6: 5 | DY6: 5 | DZ6: 2 | EA6: 5 | EB6: 3 | EC6: 5 | ED6: 5 | EE6: 5 | EF6: 0 | EG6: 0 | EH6: 0 | EI6: 1 | EJ6: 5 | EK6: 5 | EL6: 5 | EM6: 0 | EN6: 0 | EO6: 0 | EP6: 0 | EQ6: 5 | ER6: 0 | ES6: 2 | ET6: 1 | EU6: 3 | EV6: 2
A7: CUR-USE_2 | B7: Rate your consumption for each of the following products:-Caffeinated soda (examples: Coke, Pepsi, Mountain Dew) | C7: 2 | D7: 2 | E7: 4 | F7: 5 | G7: 3 | H7: 3 | I7: 4 | J7: 3 | K7: 3 | L7: 5 | M7: 3 | N7: 4 | O7: 5 | P7: 2 | Q7: 3 | R7: 2 | S7: 2 | T7: 2 | U7: 2 | V7: 2 | W7: 1 | X7: 2 | Y7: 2 | Z7: 2 | AA7: 4 | AB7: 3 | AC7: 3 | AD7: 2 | AE7: 2 | AF7: 4 | AG7: 4 | AH7: 2 | AI7: 4 | AJ7: 3 | AK7: 3 | AL7: 4 | AM7: 5 | AN7: 2 | AO7: 4 | AP7: 4 | AQ7: 3 | AR7: 2 | AS7: 3 | AT7: 2 | AU7: 3 | AV7: 2 | AW7: 5 | AX7: 5 | AY7: 3 | AZ7: 2 | BA7: 2 | BB7: 2 | BC7: 2 | BD7: 2 | BE7: 5 | BF7: 2 | BG7: 2 | BH7: 2 | BI7: 4 | BJ7: 2 | BK7: 2 | BL7: 4 | BM7: 2 | BN7: 2 | BO7: 4 | BP7: 1 | BQ7: 2 | BR7: 3 | BS7: 2 | BT7: 5 | BU7: 2 | BV7: 5 | BW7: 3 | BX7: 3 | BY7: 2 | BZ7: 2 | CA7: 2 | CB7: 2 | CC7: 2 | CD7: 2 | CE7: 2 | CF7: 4 | CG7: 4 | CH7: 2 | CI7: 5 | CJ7: 3 | CK7: 4 | CL7: 5 | CM7: 3 | CN7: 3 | CO7: 2 | CP7: 4 | CQ7: 5 | CR7: 5 | CS7: 2 | CT7: 3 | CU7: 2 | CV7: 2 | CW7: 5 | CX7: 3 | CY7: 2 | CZ7: 5 | DA7: 5 | DB7: 3 | DC7: 2 | DD7: 2 | DE7: 2 | DF7: 5 | DG7: 4 | DH7: 5 | DI7: 4 | DJ7: 2 | DK7: 3 | DL7: 5 | DM7: 2 | DN7: 3 | DO7: 2 | DP7: 2 | DQ7: 4 | DR7: 5 | DS7: 2 | DT7: 5 | DU7: 1 | DV7: 4 | DW7: 5 | DX7: 5 | DY7: 5 | DZ7: 5 | EA7: 2 | EB7: 2 | EC7: 3 | ED7: 5 | EE7: 2 | EF7: 0 | EG7: 0 | EH7: 0 | EI7: 4 | EJ7: 2 | EK7: 2 | EL7: 3 | EM7: 0 | EN7: 0 | EO7: 0 | EP7: 0 | EQ7: 2 | ER7: 0 | ES7: 2 | ET7: 2 | EU7: 4 | EV7: 2
A8: CUR-USE_3 | B8: Rate your consumption for each of the following products:-Any brand of caffeinated energy drink (examples: Monster, Rockstar, Red Bull) | C8: 1 | D8: 1 | E8: 1 | F8: 2 | G8: 1 | H8: 1 | I8: 2 | J8: 2 | K8: 1 | L8: 1 | M8: 1 | N8: 1 | O8: 2 | P8: 2 | Q8: 2 | R8: 2 | S8: 2 | T8: 2 | U8: 1 | V8: 1 | W8: 1 | X8: 1 | Y8: 1 | Z8: 2 | AA8: 2 | AB8: 3 | AC8: 2 | AD8: 2 | AE8: 2 | AF8: 2 | AG8: 2 | AH8: 1 | AI8: 1 | AJ8: 2 | AK8: 2 | AL8: 4 | AM8: 2 | AN8: 2 | AO8: 1 | AP8: 1 | AQ8: 4 | AR8: 2 | AS8: 1 | AT8: 2 | AU8: 0 | AV8: 1 | AW8: 1 | AX8: 2 | AY8: 4 | AZ8: 2 | BA8: 2 | BB8: 1 | BC8: 2 | BD8: 1 | BE8: 1 | BF8: 1 | BG8: 2 | BH8: 2 | BI8: 1 | BJ8: 2 | BK8: 1 | BL8: 2 | BM8: 2 | BN8: 2 | BO8: 2 | BP8: 1 | BQ8: 1 | BR8: 2 | BS8: 1 | BT8: 4 | BU8: 1 | BV8: 1 | BW8: 1 | BX8: 1 | BY8: 1 | BZ8: 1 | CA8: 2 | CB8: 1 | CC8: 2 | CD8: 1 | CE8: 1 | CF8: 2 | CG8: 1 | CH8: 2 | CI8: 2 | CJ8: 2 | CK8: 2 | CL8: 1 | CM8: 1 | CN8: 1 | CO8: 2 | CP8: 1 | CQ8: 1 | CR8: 2 | CS8: 1 | CT8: 1 | CU8: 2 | CV8: 2 | CW8: 1 | CX8: 2 | CY8: 2 | CZ8: 1 | DA8: 2 | DB8: 1 | DC8: 2 | DD8: 2 | DE8: 1 | DF8: 1 | DG8: 1 | DH8: 2 | DI8: 2 | DJ8: 2 | DK8: 1 | DL8: 1 | DM8: 1 | DN8: 1 | DO8: 2 | DP8: 2 | DQ8: 1 | DR8: 2 | DS8: 1 | DT8: 2 | DU8: 1 | DV8: 1 | DW8: 1 | DX8: 3 | DY8: 2 | DZ8: 2 | EA8: 2 | EB8: 1 | EC8: 2 | ED8: 2 | EE8: 1 | EF8: 0 | EG8: 0 | EH8: 0 | EI8: 1 | EJ8: 2 | EK8: 2 | EL8: 1 | EM8: 0 | EN8: 0 | EO8: 0 | EP8: 0 | EQ8: 1 | ER8: 0 | ES8: 2 | ET8: 1 | EU8: 2 | EV8: 1
A9: CUR-USE_4 | B9: Rate your consumption for each of the following products:-Any brand of energy shots (example: 5-hr energy) | C9: 1 | D9: 1 | E9: 1 | F9: 1 | G9: 1 | H9: 1 | I9: 1 | J9: 1 | K9: 1 | L9: 1 | M9: 1 | N9: 1 | O9: 2 | P9: 1 | Q9: 2 | R9: 2 | S9: 2 | T9: 1 | U9: 1 | V9: 1 | W9: 1 | X9: 1 | Y9: 1 | Z9: 1 | AA9: 1 | AB9: 1 | AC9: 2 | AD9: 1 | AE9: 1 | AF9: 2 | AG9: 1 | AH9: 1 | AI9: 1 | AJ9: 2 | AK9: 1 | AL9: 4 | AM9: 1 | AN9: 2 | AO9: 1 | AP9: 1 | AQ9: 3 | AR9: 2 | AS9: 1 | AT9: 2 | AU9: 1 | AV9: 1 | AW9: 1 | AX9: 2 | AY9: 1 | AZ9: 2 | BA9: 2 | BB9: 1 | BC9: 1 | BD9: 1 | BE9: 1 | BF9: 1 | BG9: 2 | BH9: 2 | BI9: 1 | BJ9: 1 | BK9: 1 | BL9: 1 | BM9: 1 | BN9: 2 | BO9: 1 | BP9: 1 | BQ9: 1 | BR9: 1 | BS9: 1 | BT9: 3 | BU9: 1 | BV9: 1 | BW9: 1 | BX9: 1 | BY9: 1 | BZ9: 1 | CA9: 1 | CB9: 1 | CC9: 1 | CD9: 1 | CE9: 1 | CF9: 1 | CG9: 1 | CH9: 2 | CI9: 1 | CJ9: 2 | CK9: 1 | CL9: 1 | CM9: 1 | CN9: 1 | CO9: 2 | CP9: 1 | CQ9: 1 | CR9: 1 | CS9: 1 | CT9: 1 | CU9: 1 | CV9: 1 | CW9: 1 | CX9: 3 | CY9: 1 | CZ9: 1 | DA9: 1 | DB9: 1 | DC9: 2 | DD9: 1 | DE9: 1 | DF9: 1 | DG9: 1 | DH9: 1 | DI9: 1 | DJ9: 2 | DK9: 1 | DL9: 1 | DM9: 1 | DN9: 1 | DO9: 1 | DP9: 1 | DQ9: 1 | DR9: 2 | DS9: 1 | DT9: 1 | DU9: 1 | DV9: 2 | DW9: 1 | DX9: 1 | DY9: 1 | DZ9: 1 | EA9: 2 | EB9: 1 | EC9: 1 | ED9: 2 | EE9: 1 | EF9: 0 | EG9: 0 | EH9: 0 | EI9: 1 | EJ9: 2 | EK9: 2 | EL9: 1 | EM9: 0 | EN9: 0 | EO9: 0 | EP9: 0 | EQ9: 1 | ER9: 0 | ES9: 1 | ET9: 1 | EU9: 1 | EV9: 1
